Workbook

Sheet Januar
B1: Arbeitszeiterfassung 2026
B4: Name: | C4: Andrea Keller-Brockmann | K4: Monat: | L4: Januar
B6: Datum | C6: Arbeitsphase | E6: Unterbrechungen | I6: Arbeitsstunden | K6: Anmerkungen
C7: Beginn | D7: Ende | E7: Beginn | F7: Ende | G7: Beginn | H7: Ende | I7: Ist | J7: Soll | K7: Anm. U/K
A8: Do | B8: 1. | I8: =D8-C8-F8+E8-H8+G8+N8+O8 -> 0 | J8: 0 | M8: =IF(OR(K8="U",K8="K"),J8,"0:00") -> 0:00 | N8: =IF(M8<>"0:00",J8,"0:00") -> 0:00 | O8: =IF(K8="0,5 U","03:51","0:00") -> 0:00 | P8: Mo | Q8: =Q21 -> 0.16666667 | R8: =IF(A8="Mo",$Q$8,IF(A8="Di",$Q$9,IF(A8="Mi",$Q$10,IF(A8="Do",$Q$11,IF(A8="Fr",$Q$12,$Q$13))))) -> 0.16666667
A9: Fr | B9: 2. | I9: =D9-C9-F9+E9-H9+G9+N9+O9 -> 0 | J9: =R9 -> 0 | M9: =IF(OR(K9="U",K9="K"),J9,"0:00") -> 0:00 | N9: =IF(M9<>"0:00",J9,"0:00") -> 0:00 | O9: =IF(K9="0,5 U","03:51","0:00") -> 0:00 | P9: Di | Q9: =Q21 -> 0.16666667 | R9: =IF(A9="Mo",$Q$8,IF(A9="Di",$Q$9,IF(A9="Mi",$Q$10,IF(A9="Do",$Q$11,IF(A9="Fr",$Q$12,$Q$13))))) -> 0
A10: Sa | B10: 3. | I10: =D10-C10-F10+E10-H10+G10+N10+O10 -> 0 | J10: =R10 -> 0 | M10: =IF(OR(K10="U",K10="K"),J10,"0:00") -> 0:00 | N10: =IF(M10<>"0:00",J10,"0:00") -> 0:00 | O10: =IF(K10="0,5 U","03:51","0:00") -> 0:00 | P10: Mi | Q10: =Q21 -> 0.16666667 | R10: =IF(A10="Mo",$Q$8,IF(A10="Di",$Q$9,IF(A10="Mi",$Q$10,IF(A10="Do",$Q$11,IF(A10="Fr",$Q$12,$Q$13))))) -> 0
A11: So | B11: 4. | I11: =D11-C11-F11+E11-H11+G11+N11+O11 -> 0 | J11: =R11 -> 0 | M11: =IF(OR(K11="U",K11="K"),J11,"0:00") -> 0:00 | N11: =IF(M11<>"0:00",J11,"0:00") -> 0:00 | O11: =IF(K11="0,5 U","03:51","0:00") -> 0:00 | P11: Do | Q11: =Q21 -> 0.16666667 | R11: =IF(A11="Mo",$Q$8,IF(A11="Di",$Q$9,IF(A11="Mi",$Q$10,IF(A11="Do",$Q$11,IF(A11="Fr",$Q$12,$Q$13))))) -> 0
A12: Mo | B12: 5. | I12: 0.16666667 | J12: =R12 -> 0.16666667 | K12: U | M12: =IF(OR(K12="U",K12="K"),J12,"0:00") -> 0.16666667 | N12: =IF(M12<>"0:00",J12,"0:00") -> 0.16666667 | O12: =IF(K12="0,5 U","03:51","0:00") -> 0:00 | P12: Fr | Q12: 0 | R12: =IF(A12="Mo",$Q$8,IF(A12="Di",$Q$9,IF(A12="Mi",$Q$10,IF(A12="Do",$Q$11,IF(A12="Fr",$Q$12,$Q$13))))) -> 0.16666667
A13: Di | B13: 6. | I13: 0.16666667 | J13: 0.16666667 | K13: U | M13: =IF(OR(K13="U",K13="K"),J13,"0:00") -> 0.16666667 | N13: =IF(M13<>"0:00",J13,"0:00") -> 0.16666667 | O13: =IF(K13="0,5 U","03:51","0:00") -> 0:00 | P13: Sa/So | Q13: 0 | R13: =IF(A13="Mo",$Q$8,IF(A13="Di",$Q$9,IF(A13="Mi",$Q$10,IF(A13="Do",$Q$11,IF(A13="Fr",$Q$12,$Q$13))))) -> 0.16666667
A14: Mi | B14: 7. | I14: 0.16666667 | J14: =R14 -> 0.16666667 | K14: U | M14: =IF(OR(K14="U",K14="K"),J14,"0:00") -> 0.16666667 | N14: =IF(M14<>"0:00",J14,"0:00") -> 0.16666667 | O14: =IF(K14="0,5 U","03:51","0:00") -> 0:00 | Q14: 0 | R14: =IF(A14="Mo",$Q$8,IF(A14="Di",$Q$9,IF(A14="Mi",$Q$10,IF(A14="Do",$Q$11,IF(A14="Fr",$Q$12,$Q$13))))) -> 0.16666667
A15: Do | B15: 8. | C15: 0.375 | D15: 0.54166667 | I15: =D15-C15-F15+E15-H15+G15+N15+O15 -> 0.16666667 | J15: =R15 -> 0.16666667 | M15: =IF(OR(K15="U",K15="K"),J15,"0:00") -> 0:00 | N15: =IF(M15<>"0:00",J15,"0:00") -> 0:00 | O15: =IF(K15="0,5 U","03:51","0:00") -> 0:00 | R15: =IF(A15="Mo",$Q$8,IF(A15="Di",$Q$9,IF(A15="Mi",$Q$10,IF(A15="Do",$Q$11,IF(A15="Fr",$Q$12,$Q$13))))) -> 0.16666667
A16: Fr | B16: 9. | I16: =D16-C16-F16+E16-H16+G16+N16+O16 -> 0 | J16: =R16 -> 0 | M16: =IF(OR(K16="U",K16="K"),J16,"0:00") -> 0:00 | N16: =IF(M16<>"0:00",J16,"0:00") -> 0:00 | O16: =IF(K16="0,5 U","03:51","0:00") -> 0:00 | Q16: 1.6666667 | R16: =IF(A16="Mo",$Q$8,IF(A16="Di",$Q$9,IF(A16="Mi",$Q$10,IF(A16="Do",$Q$11,IF(A16="Fr",$Q$12,$Q$13))))) -> 0
A17: Sa | B17: 10. | I17: =D17-C17-F17+E17-H17+G17+N17+O17 -> 0 | J17: =R17 -> 0 | M17: =IF(OR(K17="U",K17="K"),J17,"0:00") -> 0:00 | N17: =IF(M17<>"0:00",J17,"0:00") -> 0:00 | O17: =IF(K17="0,5 U","03:51","0:00") -> 0:00 | Q17: 40 | R17: =IF(A17="Mo",$Q$8,IF(A17="Di",$Q$9,IF(A17="Mi",$Q$10,IF(A17="Do",$Q$11,IF(A17="Fr",$Q$12,$Q$13))))) -> 0
A18: So | B18: 11. | I18: =D18-C18-F18+E18-H18+G18+N18+O18 -> 0 | J18: =R18 -> 0 | M18: =IF(OR(K18="U",K18="K"),J18,"0:00") -> 0:00 | N18: =IF(M18<>"0:00",J18,"0:00") -> 0:00 | O18: =IF(K18="0,5 U","03:51","0:00") -> 0:00 | Q18: =Q16/100*Q17 -> 0.66666667 | R18: =IF(A18="Mo",$Q$8,IF(A18="Di",$Q$9,IF(A18="Mi",$Q$10,IF(A18="Do",$Q$11,IF(A18="Fr",$Q$12,$Q$13))))) -> 0
A19: Mo | B19: 12. | I19: =D19-C19-F19+E19-H19+G19+N19+O19 -> 0.16666667 | J19: =R19 -> 0.16666667 | K19: K | M19: =IF(OR(K19="U",K19="K"),J19,"0:00") -> 0.16666667 | N19: =IF(M19<>"0:00",J19,"0:00") -> 0.16666667 | O19: =IF(K19="0,5 U","03:51","0:00") -> 0:00 | R19: =IF(A19="Mo",$Q$8,IF(A19="Di",$Q$9,IF(A19="Mi",$Q$10,IF(A19="Do",$Q$11,IF(A19="Fr",$Q$12,$Q$13))))) -> 0.16666667
A20: Di | B20: 13. | I20: =D20-C20-F20+E20-H20+G20+N20+O20 -> 0.16666667 | J20: =R20 -> 0.16666667 | K20: K | M20: =IF(OR(K20="U",K20="K"),J20,"0:00") -> 0.16666667 | N20: =IF(M20<>"0:00",J20,"0:00") -> 0.16666667 | O20: =IF(K20="0,5 U","03:51","0:00") -> 0:00 | P20: TW | Q20: 4 | R20: =IF(A20="Mo",$Q$8,IF(A20="Di",$Q$9,IF(A20="Mi",$Q$10,IF(A20="Do",$Q$11,IF(A20="Fr",$Q$12,$Q$13))))) -> 0.16666667
A21: Mi | B21: 14. | I21: =D21-C21-F21+E21-H21+G21+N21+O21 -> 0.16666667 | J21: =R21 -> 0.16666667 | K21: K | M21: =IF(OR(K21="U",K21="K"),J21,"0:00") -> 0.16666667 | N21: =IF(M21<>"0:00",J21,"0:00") -> 0.16666667 | O21: =IF(K21="0,5 U","03:51","0:00") -> 0:00 | Q21: =Q18/Q20 -> 0.16666667 | R21: =IF(A21="Mo",$Q$8,IF(A21="Di",$Q$9,IF(A21="Mi",$Q$10,IF(A21="Do",$Q$11,IF(A21="Fr",$Q$12,$Q$13))))) -> 0.16666667
A22: Do | B22: 15. | I22: =D22-C22-F22+E22-H22+G22+N22+O22 -> 0.16666667 | J22: =R22 -> 0.16666667 | K22: K | M22: =IF(OR(K22="U",K22="K"),J22,"0:00") -> 0.16666667 | N22: =IF(M22<>"0:00",J22,"0:00") -> 0.16666667 | O22: =IF(K22="0,5 U","03:51","0:00") -> 0:00 | R22: =IF(A22="Mo",$Q$8,IF(A22="Di",$Q$9,IF(A22="Mi",$Q$10,IF(A22="Do",$Q$11,IF(A22="Fr",$Q$12,$Q$13))))) -> 0.16666667
A23: Fr | B23: 16. | I23: =D23-C23-F23+E23-H23+G23+N23+O23 -> 0 | J23: =R23 -> 0 | M23: =IF(OR(K23="U",K23="K"),J23,"0:00") -> 0:00 | N23: =IF(M23<>"0:00",J23,"0:00") -> 0:00 | O23: =IF(K23="0,5 U","03:51","0:00") -> 0:00 | R23: =IF(A23="Mo",$Q$8,IF(A23="Di",$Q$9,IF(A23="Mi",$Q$10,IF(A23="Do",$Q$11,IF(A23="Fr",$Q$12,$Q$13))))) -> 0
A24: Sa | B24: 17. | I24: =D24-C24-F24+E24-H24+G24+N24+O24 -> 0 | J24: =R24 -> 0 | M24: =IF(OR(K24="U",K24="K"),J24,"0:00") -> 0:00 | N24: =IF(M24<>"0:00",J24,"0:00") -> 0:00 | O24: =IF(K24="0,5 U","03:51","0:00") -> 0:00 | R24: =IF(A24="Mo",$Q$8,IF(A24="Di",$Q$9,IF(A24="Mi",$Q$10,IF(A24="Do",$Q$11,IF(A24="Fr",$Q$12,$Q$13))))) -> 0
A25: So | B25: 18. | I25: =D25-C25-F25+E25-H25+G25+N25+O25 -> 0 | J25: =R25 -> 0 | M25: =IF(OR(K25="U",K25="K"),J25,"0:00") -> 0:00 | N25: =IF(M25<>"0:00",J25,"0:00") -> 0:00 | O25: =IF(K25="0,5 U","03:51","0:00") -> 0:00 | R25: =IF(A25="Mo",$Q$8,IF(A25="Di",$Q$9,IF(A25="Mi",$Q$10,IF(A25="Do",$Q$11,IF(A25="Fr",$Q$12,$Q$13))))) -> 0
A26: Mo | B26: 19. | C26: 0.35416667 | D26: 0.51041667 | I26: =D26-C26-F26+E26-H26+G26+N26+O26 -> 0.15625 | J26: =R26 -> 0.16666667 | M26: =IF(OR(K26="U",K26="K"),J26,"0:00") -> 0:00 | N26: =IF(M26<>"0:00",J26,"0:00") -> 0:00 | O26: =IF(K26="0,5 U","03:51","0:00") -> 0:00 | R26: =IF(A26="Mo",$Q$8,IF(A26="Di",$Q$9,IF(A26="Mi",$Q$10,IF(A26="Do",$Q$11,IF(A26="Fr",$Q$12,$Q$13))))) -> 0.16666667
A27: Di | B27: 20. | C27: 0.38541667 | D27: 0.66666667 | E27: 0.51041667 | F27: 0.53125 | I27: =D27-C27-F27+E27-H27+G27+N27+O27 -> 0.26041667 | J27: =R27 -> 0.16666667 | M27: =IF(OR(K27="U",K27="K"),J27,"0:00") -> 0:00 | N27: =IF(M27<>"0:00",J27,"0:00") -> 0:00 | O27: =IF(K27="0,5 U","03:51","0:00") -> 0:00 | R27: =IF(A27="Mo",$Q$8,IF(A27="Di",$Q$9,IF(A27="Mi",$Q$10,IF(A27="Do",$Q$11,IF(A27="Fr",$Q$12,$Q$13))))) -> 0.16666667
A28: Mi | B28: 21. | C28: 0.38541667 | D28: 0.51041667 | I28: =D28-C28-F28+E28-H28+G28+N28+O28 -> 0.125 | J28: =R28 -> 0.16666667 | M28: =IF(OR(K28="U",K28="K"),J28,"0:00") -> 0:00 | N28: =IF(M28<>"0:00",J28,"0:00") -> 0:00 | O28: =IF(K28="0,5 U","03:51","0:00") -> 0:00 | R28: =IF(A28="Mo",$Q$8,IF(A28="Di",$Q$9,IF(A28="Mi",$Q$10,IF(A28="Do",$Q$11,IF(A28="Fr",$Q$12,$Q$13))))) -> 0.16666667
A29: Do | B29: 22. | C29: 0.375 | D29: 0.5 | I29: =D29-C29-F29+E29-H29+G29+N29+O29 -> 0.125 | J29: =R29 -> 0.16666667 | M29: =IF(OR(K29="U",K29="K"),J29,"0:00") -> 0:00 | N29: =IF(M29<>"0:00",J29,"0:00") -> 0:00 | O29: =IF(K29="0,5 U","03:51","0:00") -> 0:00 | R29: =IF(A29="Mo",$Q$8,IF(A29="Di",$Q$9,IF(A29="Mi",$Q$10,IF(A29="Do",$Q$11,IF(A29="Fr",$Q$12,$Q$13))))) -> 0.16666667
A30: Fr | B30: 23. | I30: =D30-C30-F30+E30-H30+G30+N30+O30 -> 0 | J30: =R30 -> 0 | M30: =IF(OR(K30="U",K30="K"),J30,"0:00") -> 0:00 | N30: =IF(M30<>"0:00",J30,"0:00") -> 0:00 | O30: =IF(K30="0,5 U","03:51","0:00") -> 0:00 | R30: =IF(A30="Mo",$Q$8,IF(A30="Di",$Q$9,IF(A30="Mi",$Q$10,IF(A30="Do",$Q$11,IF(A30="Fr",$Q$12,$Q$13))))) -> 0
A31: Sa | B31: 24. | I31: =D31-C31-F31+E31-H31+G31+N31+O31 -> 0 | J31: =R31 -> 0 | M31: =IF(OR(K31="U",K31="K"),J31,"0:00") -> 0:00 | N31: =IF(M31<>"0:00",J31,"0:00") -> 0:00 | O31: =IF(K31="0,5 U","03:51","0:00") -> 0:00 | R31: =IF(A31="Mo",$Q$8,IF(A31="Di",$Q$9,IF(A31="Mi",$Q$10,IF(A31="Do",$Q$11,IF(A31="Fr",$Q$12,$Q$13))))) -> 0
A32: So | B32: 25. | I32: =D32-C32-F32+E32-H32+G32+N32+O32 -> 0 | J32: =R32 -> 0 | M32: =IF(OR(K32="U",K32="K"),J32,"0:00") -> 0:00 | N32: =IF(M32<>"0:00",J32,"0:00") -> 0:00 | O32: =IF(K32="0,5 U","03:51","0:00") -> 0:00 | R32: =IF(A32="Mo",$Q$8,IF(A32="Di",$Q$9,IF(A32="Mi",$Q$10,IF(A32="Do",$Q$11,IF(A32="Fr",$Q$12,$Q$13))))) -> 0
A33: Mo | B33: 26. | C33: 0.35416667 | D33: 0.51041667 | I33: =D33-C33-F33+E33-H33+G33+N33+O33 -> 0.15625 | J33: =R33 -> 0.16666667 | M33: =IF(OR(K33="U",K33="K"),J33,"0:00") -> 0:00 | N33: =IF(M33<>"0:00",J33,"0:00") -> 0:00 | O33: =IF(K33="0,5 U","03:51","0:00") -> 0:00 | R33: =IF(A33="Mo",$Q$8,IF(A33="Di",$Q$9,IF(A33="Mi",$Q$10,IF(A33="Do",$Q$11,IF(A33="Fr",$Q$12,$Q$13))))) -> 0.16666667
A34: Di | B34: 27. | C34: 0.38541667 | D34: 0.66666667 | E34: 0.51041667 | F34: 0.53125 | I34: =D34-C34-F34+E34-H34+G34+N34+O34 -> 0.26041667 | J34: =R34 -> 0.16666667 | M34: =IF(OR(K34="U",K34="K"),J34,"0:00") -> 0:00 | N34: =IF(M34<>"0:00",J34,"0:00") -> 0:00 | O34: =IF(K34="0,5 U","03:51","0:00") -> 0:00 | R34: =IF(A34="Mo",$Q$8,IF(A34="Di",$Q$9,IF(A34="Mi",$Q$10,IF(A34="Do",$Q$11,IF(A34="Fr",$Q$12,$Q$13))))) -> 0.16666667
A35: Mi | B35: 28. | C35: 0.38541667 | D35: 0.51041667 | I35: =D35-C35-F35+E35-H35+G35+N35+O35 -> 0.125 | J35: =R35 -> 0.16666667 | M35: =IF(OR(K35="U",K35="K"),J35,"0:00") -> 0:00 | N35: =IF(M35<>"0:00",J35,"0:00") -> 0:00 | O35: =IF(K35="0,5 U","03:51","0:00") -> 0:00 | R35: =IF(A35="Mo",$Q$8,IF(A35="Di",$Q$9,IF(A35="Mi",$Q$10,IF(A35="Do",$Q$11,IF(A35="Fr",$Q$12,$Q$13))))) -> 0.16666667
A36: Do | B36: 29. | C36: 0.375 | D36: 0.5 | I36: =D36-C36-F36+E36-H36+G36+N36+O36 -> 0.125 | J36: =R36 -> 0.16666667 | M36: =IF(OR(K36="U",K36="K"),J36,"0:00") -> 0:00 | N36: =IF(M36<>"0:00",J36,"0:00") -> 0:00 | O36: =IF(K36="0,5 U","03:51","0:00") -> 0:00 | R36: =IF(A36="Mo",$Q$8,IF(A36="Di",$Q$9,IF(A36="Mi",$Q$10,IF(A36="Do",$Q$11,IF(A36="Fr",$Q$12,$Q$13))))) -> 0.16666667
A37: Fr | B37: 30. | I37: =D37-C37-F37+E37-H37+G37+N37+O37 -> 0 | J37: =R37 -> 0 | M37: =IF(OR(K37="U",K37="K"),J37,"0:00") -> 0:00 | N37: =IF(M37<>"0:00",J37,"0:00") -> 0:00 | O37: =IF(K37="0,5 U","03:51","0:00") -> 0:00 | R37: =IF(A37="Mo",$Q$8,IF(A37="Di",$Q$9,IF(A37="Mi",$Q$10,IF(A37="Do",$Q$11,IF(A37="Fr",$Q$12,$Q$13))))) -> 0
A38: Sa | B38: 31. | I38: =D38-C38-F38+E38-H38+G38+N38+O38 -> 0 | J38: =R38 -> 0 | M38: =IF(OR(K38="U",K38="K"),J38,"0:00") -> 0:00 | N38: =IF(M38<>"0:00",J38,"0:00") -> 0:00 | O38: =IF(K38="0,5 U","03:51","0:00") -> 0:00 | R38: =IF(A38="Mo",$Q$8,IF(A38="Di",$Q$9,IF(A38="Mi",$Q$10,IF(A38="Do",$Q$11,IF(A38="Fr",$Q$12,$Q$13))))) -> 0
I39: Ist | J39: Soll
E40: monatliche Arbeitstunden | I40: =SUM(I8:I38) -> 2.6666667 | J40: =SUM(J8:J38) -> 2.6666667 | M40: =SUM(M8:M38) -> 1.1666667
C43: Ist-Arbeitsstunden | G43: =I40 -> 2.6666667 | J43: Erholungsurlaub
J44: Resturlaub 2025 | L44: 4
C45: zzgl. Zeitguthaben Vormonat | G45: 0.26041667 | J45: Jahresurlaub 2026 | L45: 24
...

Sheet Februar
B1: =Januar!B1 -> Arbeitszeiterfassung 2026
B4: Name: | C4: =Januar!C4 -> Andrea Keller-Brockmann | K4: Monat: | L4: Februar
B6: Datum | C6: Arbeitsphase | E6: Unterbrechungen | I6: Arbeitsstunden | K6: Anmerkungen
C7: Beginn | D7: Ende | E7: Beginn | F7: Ende | G7: Beginn | H7: Ende | I7: Ist | J7: Soll | K7: =Januar!K7 -> Anm. U/K
A8: So | B8: 1. | I8: =D8-C8-F8+E8-H8+G8+N8+O8 -> 0 | J8: =R8 -> 0 | M8: =IF(OR(K8="U",K8="K"),J8,"0:00") -> 0:00 | N8: =IF(M8<>"0:00",J8,"0:00") -> 0:00 | O8: =IF(K8="0,5 U","03:51","0:00") -> 0:00 | R8: =IF(A8="Mo",Januar!$Q$8,IF(A8="Di",Januar!$Q$9,IF(A8="Mi",Januar!$Q$10,IF(A8="Do",Januar!$Q$11,IF(A8="Fr",Januar!$Q$12,Januar!$Q$13))))) -> 0
A9: Mo | B9: 2. | C9: 0.35416667 | D9: 0.51041667 | I9: =D9-C9-F9+E9-H9+G9+N9+O9 -> 0.15625 | J9: =R9 -> 0.16666667 | M9: =IF(OR(K9="U",K9="K"),J9,"0:00") -> 0:00 | N9: =IF(M9<>"0:00",J9,"0:00") -> 0:00 | O9: =IF(K9="0,5 U","03:51","0:00") -> 0:00 | R9: =IF(A9="Mo",Januar!$Q$8,IF(A9="Di",Januar!$Q$9,IF(A9="Mi",Januar!$Q$10,IF(A9="Do",Januar!$Q$11,IF(A9="Fr",Januar!$Q$12,Januar!$Q$13))))) -> 0.16666667
A10: Di | B10: 3. | C10: 0.38541667 | D10: 0.66666667 | E10: 0.5 | F10: 0.53125 | I10: =D10-C10-F10+E10-H10+G10+N10+O10 -> 0.25 | J10: =R10 -> 0.16666667 | M10: =IF(OR(K10="U",K10="K"),J10,"0:00") -> 0:00 | N10: =IF(M10<>"0:00",J10,"0:00") -> 0:00 | O10: =IF(K10="0,5 U","03:51","0:00") -> 0:00 | R10: =IF(A10="Mo",Januar!$Q$8,IF(A10="Di",Januar!$Q$9,IF(A10="Mi",Januar!$Q$10,IF(A10="Do",Januar!$Q$11,IF(A10="Fr",Januar!$Q$12,Januar!$Q$13))))) -> 0.16666667
A11: Mi | B11: 4. | C11: 0.38541667 | D11: 0.51041667 | I11: =D11-C11-F11+E11-H11+G11+N11+O11 -> 0.125 | J11: =R11 -> 0.16666667 | M11: =IF(OR(K11="U",K11="K"),J11,"0:00") -> 0:00 | N11: =IF(M11<>"0:00",J11,"0:00") -> 0:00 | O11: =IF(K11="0,5 U","03:51","0:00") -> 0:00 | R11: =IF(A11="Mo",Januar!$Q$8,IF(A11="Di",Januar!$Q$9,IF(A11="Mi",Januar!$Q$10,IF(A11="Do",Januar!$Q$11,IF(A11="Fr",Januar!$Q$12,Januar!$Q$13))))) -> 0.16666667
A12: Do | B12: 5. | C12: 0.375 | D12: 0.5 | I12: =D12-C12-F12+E12-H12+G12+N12+O12 -> 0.125 | J12: =R12 -> 0.16666667 | M12: =IF(OR(K12="U",K12="K"),J12,"0:00") -> 0:00 | N12: =IF(M12<>"0:00",J12,"0:00") -> 0:00 | O12: =IF(K12="0,5 U","03:51","0:00") -> 0:00 | R12: =IF(A12="Mo",Januar!$Q$8,IF(A12="Di",Januar!$Q$9,IF(A12="Mi",Januar!$Q$10,IF(A12="Do",Januar!$Q$11,IF(A12="Fr",Januar!$Q$12,Januar!$Q$13))))) -> 0.16666667
A13: Fr | B13: 6. | I13: =D13-C13-F13+E13-H13+G13+N13+O13 -> 0 | J13: =R13 -> 0 | M13: =IF(OR(K13="U",K13="K"),J13,"0:00") -> 0:00 | N13: =IF(M13<>"0:00",J13,"0:00") -> 0:00 | O13: =IF(K13="0,5 U","03:51","0:00") -> 0:00 | R13: =IF(A13="Mo",Januar!$Q$8,IF(A13="Di",Januar!$Q$9,IF(A13="Mi",Januar!$Q$10,IF(A13="Do",Januar!$Q$11,IF(A13="Fr",Januar!$Q$12,Januar!$Q$13))))) -> 0
A14: Sa | B14: 7. | I14: =D14-C14-F14+E14-H14+G14+N14+O14 -> 0 | J14: =R14 -> 0 | M14: =IF(OR(K14="U",K14="K"),J14,"0:00") -> 0:00 | N14: =IF(M14<>"0:00",J14,"0:00") -> 0:00 | O14: =IF(K14="0,5 U","03:51","0:00") -> 0:00 | R14: =IF(A14="Mo",Januar!$Q$8,IF(A14="Di",Januar!$Q$9,IF(A14="Mi",Januar!$Q$10,IF(A14="Do",Januar!$Q$11,IF(A14="Fr",Januar!$Q$12,Januar!$Q$13))))) -> 0
A15: So | B15: 8. | I15: =D15-C15-F15+E15-H15+G15+N15+O15 -> 0 | J15: =R15 -> 0 | M15: =IF(OR(K15="U",K15="K"),J15,"0:00") -> 0:00 | N15: =IF(M15<>"0:00",J15,"0:00") -> 0:00 | O15: =IF(K15="0,5 U","03:51","0:00") -> 0:00 | R15: =IF(A15="Mo",Januar!$Q$8,IF(A15="Di",Januar!$Q$9,IF(A15="Mi",Januar!$Q$10,IF(A15="Do",Januar!$Q$11,IF(A15="Fr",Januar!$Q$12,Januar!$Q$13))))) -> 0
A16: Mo | B16: 9. | C16: 0.35416667 | D16: 0.51041667 | I16: =D16-C16-F16+E16-H16+G16+N16+O16 -> 0.15625 | J16: =R16 -> 0.16666667 | M16: =IF(OR(K16="U",K16="K"),J16,"0:00") -> 0:00 | N16: =IF(M16<>"0:00",J16,"0:00") -> 0:00 | O16: =IF(K16="0,5 U","03:51","0:00") -> 0:00 | R16: =IF(A16="Mo",Januar!$Q$8,IF(A16="Di",Januar!$Q$9,IF(A16="Mi",Januar!$Q$10,IF(A16="Do",Januar!$Q$11,IF(A16="Fr",Januar!$Q$12,Januar!$Q$13))))) -> 0.16666667
A17: Di | B17: 10. | C17: 0 | D17: 0 | I17: =D17-C17-F17+E17-H17+G17+N17+O17 -> 0 | J17: =R17 -> 0.16666667 | K17: Ü-frei | M17: =IF(OR(K17="U",K17="K"),J17,"0:00") -> 0:00 | N17: =IF(M17<>"0:00",J17,"0:00") -> 0:00 | O17: =IF(K17="0,5 U","03:51","0:00") -> 0:00 | R17: =IF(A17="Mo",Januar!$Q$8,IF(A17="Di",Januar!$Q$9,IF(A17="Mi",Januar!$Q$10,IF(A17="Do",Januar!$Q$11,IF(A17="Fr",Januar!$Q$12,Januar!$Q$13))))) -> 0.16666667
A18: Mi | B18: 11. | C18: 0.38541667 | D18: 0.51041667 | I18: =D18-C18-F18+E18-H18+G18+N18+O18 -> 0.125 | J18: =R18 -> 0.16666667 | M18: =IF(OR(K18="U",K18="K"),J18,"0:00") -> 0:00 | N18: =IF(M18<>"0:00",J18,"0:00") -> 0:00 | O18: =IF(K18="0,5 U","03:51","0:00") -> 0:00 | R18: =IF(A18="Mo",Januar!$Q$8,IF(A18="Di",Januar!$Q$9,IF(A18="Mi",Januar!$Q$10,IF(A18="Do",Januar!$Q$11,IF(A18="Fr",Januar!$Q$12,Januar!$Q$13))))) -> 0.16666667
A19: Do | B19: 12. | C19: 0.375 | D19: 0.6875 | E19: 0.5 | F19: 0.5625 | I19: =D19-C19-F19+E19-H19+G19+N19+O19 -> 0.25 | J19: =R19 -> 0.16666667 | M19: =IF(OR(K19="U",K19="K"),J19,"0:00") -> 0:00 | N19: =IF(M19<>"0:00",J19,"0:00") -> 0:00 | O19: =IF(K19="0,5 U","03:51","0:00") -> 0:00 | R19: =IF(A19="Mo",Januar!$Q$8,IF(A19="Di",Januar!$Q$9,IF(A19="Mi",Januar!$Q$10,IF(A19="Do",Januar!$Q$11,IF(A19="Fr",Januar!$Q$12,Januar!$Q$13))))) -> 0.16666667
A20: Fr | B20: 13. | I20: =D20-C20-F20+E20-H20+G20+N20+O20 -> 0 | J20: =R20 -> 0 | M20: =IF(OR(K20="U",K20="K"),J20,"0:00") -> 0:00 | N20: =IF(M20<>"0:00",J20,"0:00") -> 0:00 | O20: =IF(K20="0,5 U","03:51","0:00") -> 0:00 | R20: =IF(A20="Mo",Januar!$Q$8,IF(A20="Di",Januar!$Q$9,IF(A20="Mi",Januar!$Q$10,IF(A20="Do",Januar!$Q$11,IF(A20="Fr",Januar!$Q$12,Januar!$Q$13))))) -> 0
A21: Sa | B21: 14. | I21: =D21-C21-F21+E21-H21+G21+N21+O21 -> 0 | J21: =R21 -> 0 | M21: =IF(OR(K21="U",K21="K"),J21,"0:00") -> 0:00 | N21: =IF(M21<>"0:00",J21,"0:00") -> 0:00 | O21: =IF(K21="0,5 U","03:51","0:00") -> 0:00 | R21: =IF(A21="Mo",Januar!$Q$8,IF(A21="Di",Januar!$Q$9,IF(A21="Mi",Januar!$Q$10,IF(A21="Do",Januar!$Q$11,IF(A21="Fr",Januar!$Q$12,Januar!$Q$13))))) -> 0
A22: So | B22: 15. | I22: =D22-C22-F22+E22-H22+G22+N22+O22 -> 0 | J22: =R22 -> 0 | M22: =IF(OR(K22="U",K22="K"),J22,"0:00") -> 0:00 | N22: =IF(M22<>"0:00",J22,"0:00") -> 0:00 | O22: =IF(K22="0,5 U","03:51","0:00") -> 0:00 | R22: =IF(A22="Mo",Januar!$Q$8,IF(A22="Di",Januar!$Q$9,IF(A22="Mi",Januar!$Q$10,IF(A22="Do",Januar!$Q$11,IF(A22="Fr",Januar!$Q$12,Januar!$Q$13))))) -> 0
A23: Mo | B23: 16. | I23: =D23-C23-F23+E23-H23+G23+N23+O23 -> 0 | J23: 0 | M23: =IF(OR(K23="U",K23="K"),J23,"0:00") -> 0:00 | N23: =IF(M23<>"0:00",J23,"0:00") -> 0:00 | O23: =IF(K23="0,5 U","03:51","0:00") -> 0:00 | R23: =IF(A23="Mo",Januar!$Q$8,IF(A23="Di",Januar!$Q$9,IF(A23="Mi",Januar!$Q$10,IF(A23="Do",Januar!$Q$11,IF(A23="Fr",Januar!$Q$12,Januar!$Q$13))))) -> 0.16666667
A24: Di | B24: 17. | C24: 0.54166667 | D24: 0.66666667 | I24: =D24-C24-F24+E24-H24+G24+N24+O24 -> 0.125 | J24: =R24 -> 0.16666667 | K24: kein Clemenshaus | M24: =IF(OR(K24="U",K24="K"),J24,"0:00") -> 0:00 | N24: =IF(M24<>"0:00",J24,"0:00") -> 0:00 | O24: =IF(K24="0,5 U","03:51","0:00") -> 0:00 | R24: =IF(A24="Mo",Januar!$Q$8,IF(A24="Di",Januar!$Q$9,IF(A24="Mi",Januar!$Q$10,IF(A24="Do",Januar!$Q$11,IF(A24="Fr",Januar!$Q$12,Januar!$Q$13))))) -> 0.16666667
A25: Mi | B25: 18. | C25: 0.38541667 | D25: 0.66666667 | E25: 0.51041667 | F25: 0.53125 | I25: =D25-C25-F25+E25-H25+G25+N25+O25 -> 0.26041667 | J25: =R25 -> 0.16666667 | K25: Aschermittwoch in 2 Kitas für Alle | M25: =IF(OR(K25="U",K25="K"),J25,"0:00") -> 0:00 | N25: =IF(M25<>"0:00",J25,"0:00") -> 0:00 | O25: =IF(K25="0,5 U","03:51","0:00") -> 0:00 | R25: =IF(A25="Mo",Januar!$Q$8,IF(A25="Di",Januar!$Q$9,IF(A25="Mi",Januar!$Q$10,IF(A25="Do",Januar!$Q$11,IF(A25="Fr",Januar!$Q$12,Januar!$Q$13))))) -> 0.16666667
A26: Do | B26: 19. | C26: 0.375 | D26: 0.5 | I26: =D26-C26-F26+E26-H26+G26+N26+O26 -> 0.125 | J26: =R26 -> 0.16666667 | M26: =IF(OR(K26="U",K26="K"),J26,"0:00") -> 0:00 | N26: =IF(M26<>"0:00",J26,"0:00") -> 0:00 | O26: =IF(K26="0,5 U","03:51","0:00") -> 0:00 | R26: =IF(A26="Mo",Januar!$Q$8,IF(A26="Di",Januar!$Q$9,IF(A26="Mi",Januar!$Q$10,IF(A26="Do",Januar!$Q$11,IF(A26="Fr",Januar!$Q$12,Januar!$Q$13))))) -> 0.16666667
A27: Fr | B27: 20. | I27: =D27-C27-F27+E27-H27+G27+N27+O27 -> 0 | J27: =R27 -> 0 | M27: =IF(OR(K27="U",K27="K"),J27,"0:00") -> 0:00 | N27: =IF(M27<>"0:00",J27,"0:00") -> 0:00 | O27: =IF(K27="0,5 U","03:51","0:00") -> 0:00 | R27: =IF(A27="Mo",Januar!$Q$8,IF(A27="Di",Januar!$Q$9,IF(A27="Mi",Januar!$Q$10,IF(A27="Do",Januar!$Q$11,IF(A27="Fr",Januar!$Q$12,Januar!$Q$13))))) -> 0
A28: Sa | B28: 21. | I28: =D28-C28-F28+E28-H28+G28+N28+O28 -> 0 | J28: =R28 -> 0 | M28: =IF(OR(K28="U",K28="K"),J28,"0:00") -> 0:00 | N28: =IF(M28<>"0:00",J28,"0:00") -> 0:00 | O28: =IF(K28="0,5 U","03:51","0:00") -> 0:00 | R28: =IF(A28="Mo",Januar!$Q$8,IF(A28="Di",Januar!$Q$9,IF(A28="Mi",Januar!$Q$10,IF(A28="Do",Januar!$Q$11,IF(A28="Fr",Januar!$Q$12,Januar!$Q$13))))) -> 0
A29: So | B29: 22. | I29: =D29-C29-F29+E29-H29+G29+N29+O29 -> 0 | J29: =R29 -> 0 | M29: =IF(OR(K29="U",K29="K"),J29,"0:00") -> 0:00 | N29: =IF(M29<>"0:00",J29,"0:00") -> 0:00 | O29: =IF(K29="0,5 U","03:51","0:00") -> 0:00 | R29: =IF(A29="Mo",Januar!$Q$8,IF(A29="Di",Januar!$Q$9,IF(A29="Mi",Januar!$Q$10,IF(A29="Do",Januar!$Q$11,IF(A29="Fr",Januar!$Q$12,Januar!$Q$13))))) -> 0
A30: Mo | B30: 23. | C30: 0.35416667 | D30: 0.51041667 | I30: =D30-C30-F30+E30-H30+G30+N30+O30 -> 0.15625 | J30: =R30 -> 0.16666667 | M30: =IF(OR(K30="U",K30="K"),J30,"0:00") -> 0:00 | N30: =IF(M30<>"0:00",J30,"0:00") -> 0:00 | O30: =IF(K30="0,5 U","03:51","0:00") -> 0:00 | R30: =IF(A30="Mo",Januar!$Q$8,IF(A30="Di",Januar!$Q$9,IF(A30="Mi",Januar!$Q$10,IF(A30="Do",Januar!$Q$11,IF(A30="Fr",Januar!$Q$12,Januar!$Q$13))))) -> 0.16666667
A31: Di | B31: 24. | C31: 0.38541667 | D31: 0.66666667 | E31: 0.51041667 | F31: 0.53125 | I31: =D31-C31-F31+E31-H31+G31+N31+O31 -> 0.26041667 | J31: =R31 -> 0.16666667 | M31: =IF(OR(K31="U",K31="K"),J31,"0:00") -> 0:00 | N31: =IF(M31<>"0:00",J31,"0:00") -> 0:00 | O31: =IF(K31="0,5 U","03:51","0:00") -> 0:00 | R31: =IF(A31="Mo",Januar!$Q$8,IF(A31="Di",Januar!$Q$9,IF(A31="Mi",Januar!$Q$10,IF(A31="Do",Januar!$Q$11,IF(A31="Fr",Januar!$Q$12,Januar!$Q$13))))) -> 0.16666667
A32: Mi | B32: 25. | C32: 0.38541667 | D32: 0.51041667 | I32: =D32-C32-F32+E32-H32+G32+N32+O32 -> 0.125 | J32: =R32 -> 0.16666667 | M32: =IF(OR(K32="U",K32="K"),J32,"0:00") -> 0:00 | N32: =IF(M32<>"0:00",J32,"0:00") -> 0:00 | O32: =IF(K32="0,5 U","03:51","0:00") -> 0:00 | R32: =IF(A32="Mo",Januar!$Q$8,IF(A32="Di",Januar!$Q$9,IF(A32="Mi",Januar!$Q$10,IF(A32="Do",Januar!$Q$11,IF(A32="Fr",Januar!$Q$12,Januar!$Q$13))))) -> 0.16666667
A33: Do | B33: 26. | C33: 0.375 | D33: 0.5 | I33: =D33-C33-F33+E33-H33+G33+N33+O33 -> 0.125 | J33: =R33 -> 0.16666667 | M33: =IF(OR(K33="U",K33="K"),J33,"0:00") -> 0:00 | N33: =IF(M33<>"0:00",J33,"0:00") -> 0:00 | O33: =IF(K33="0,5 U","03:51","0:00") -> 0:00 | R33: =IF(A33="Mo",Januar!$Q$8,IF(A33="Di",Januar!$Q$9,IF(A33="Mi",Januar!$Q$10,IF(A33="Do",Januar!$Q$11,IF(A33="Fr",Januar!$Q$12,Januar!$Q$13))))) -> 0.16666667
A34: Fr | B34: 27. | I34: =D34-C34-F34+E34-H34+G34+N34+O34 -> 0 | J34: =R34 -> 0 | M34: =IF(OR(K34="U",K34="K"),J34,"0:00") -> 0:00 | N34: =IF(M34<>"0:00",J34,"0:00") -> 0:00 | O34: =IF(K34="0,5 U","03:51","0:00") -> 0:00 | R34: =IF(A34="Mo",Januar!$Q$8,IF(A34="Di",Januar!$Q$9,IF(A34="Mi",Januar!$Q$10,IF(A34="Do",Januar!$Q$11,IF(A34="Fr",Januar!$Q$12,Januar!$Q$13))))) -> 0
A35: Sa | B35: 28. | I35: =D35-C35-F35+E35-H35+G35+N35+O35 -> 0 | J35: =R35 -> 0 | M35: =IF(OR(K35="U",K35="K"),J35,"0:00") -> 0:00 | N35: =IF(M35<>"0:00",J35,"0:00") -> 0:00 | O35: =IF(K35="0,5 U","03:51","0:00") -> 0:00 | R35: =IF(A35="Mo",Januar!$Q$8,IF(A35="Di",Januar!$Q$9,IF(A35="Mi",Januar!$Q$10,IF(A35="Do",Januar!$Q$11,IF(A35="Fr",Januar!$Q$12,Januar!$Q$13))))) -> 0
I36: Ist | J36: Soll
E37: monatliche Arbeitstunden | I37: =SUM(I8:I35) -> 2.3645833 | J37: =SUM(J8:J35) -> 2.5
C42: Ist-Arbeitsstunden | G42: =I37 -> 2.3645833 | J42: Erholungsurlaub
J43: =Januar!J44 -> Resturlaub 2025 | L43: =Januar!L44 -> 4
C44: zzgl. Zeitguthaben Vormonat | G44: =Januar!G50 -> 0.26041667 | J44: =Januar!J45 -> Jahresurlaub 2026 | L44: =Januar!L45 -> 24
C45: abzgl. Zeitdefizit Vormonat | F45: - | G45: =Januar!G51 -> 00:00 | J45: =Januar!J46 -> Zusatzurlaub SGB IX | L45: =Januar!L46 -> 0
J46: =Januar!J47 -> Gesamturlaub 2026 | L46: =Januar!L47 -> 28
C47: abzgl. Soll-Arbeitstunden | G47: =J37 -> 2.5 | J47: =Januar!J48 -> genommener Urlaub | L47: =M48+0.5*N48+Januar!L48 -> 3
...

Sheet März
B1: =Januar!B1 -> Arbeitszeiterfassung 2026
B4: Name: | C4: =Januar!C4 -> Andrea Keller-Brockmann | K4: Monat: | L4: März
B6: Datum | C6: Arbeitsphase | E6: Unterbrechungen | I6: Arbeitsstunden | K6: Anmerkungen
C7: Beginn | D7: Ende | E7: Beginn | F7: Ende | G7: Beginn | H7: Ende | I7: Ist | J7: Soll | K7: Anm. U/K
A8: So | B8: 1. | I8: =D8-C8-F8+E8-H8+G8+N8+O8 -> 0 | J8: 0 | M8: =IF(OR(K8="U",K8="K"),J8,"0:00") -> 0:00 | N8: =IF(M8<>"0:00",J8,"0:00") -> 0:00 | O8: =IF(K8="0,5 U","03:51","0:00") -> 0:00 | R8: =IF(A8="Mo",Januar!$Q$8,IF(A8="Di",Januar!$Q$9,IF(A8="Mi",Januar!$Q$10,IF(A8="Do",Januar!$Q$11,IF(A8="Fr",Januar!$Q$12,Januar!$Q$13))))) -> 0
A9: Mo | B9: 2. | C9: 0.35416667 | D9: 0.51041667 | I9: =D9-C9-F9+E9-H9+G9+N9+O9 -> 0.15625 | J9: =R9 -> 0.16666667 | M9: =IF(OR(K9="U",K9="K"),J9,"0:00") -> 0:00 | N9: =IF(M9<>"0:00",J9,"0:00") -> 0:00 | O9: =IF(K9="0,5 U","03:51","0:00") -> 0:00 | R9: =IF(A9="Mo",Januar!$Q$8,IF(A9="Di",Januar!$Q$9,IF(A9="Mi",Januar!$Q$10,IF(A9="Do",Januar!$Q$11,IF(A9="Fr",Januar!$Q$12,Januar!$Q$13))))) -> 0.16666667
A10: Di | B10: 3. | C10: 0.38541667 | D10: 0.66666667 | E10: 0.51041667 | F10: 0.53125 | I10: =D10-C10-F10+E10-H10+G10+N10+O10 -> 0.26041667 | J10: =R10 -> 0.16666667 | M10: =IF(OR(K10="U",K10="K"),J10,"0:00") -> 0:00 | N10: =IF(M10<>"0:00",J10,"0:00") -> 0:00 | O10: =IF(K10="0,5 U","03:51","0:00") -> 0:00 | R10: =IF(A10="Mo",Januar!$Q$8,IF(A10="Di",Januar!$Q$9,IF(A10="Mi",Januar!$Q$10,IF(A10="Do",Januar!$Q$11,IF(A10="Fr",Januar!$Q$12,Januar!$Q$13))))) -> 0.16666667
A11: Mi | B11: 4. | C11: 0.38541667 | D11: 0.51041667 | I11: =D11-C11-F11+E11-H11+G11+N11+O11 -> 0.125 | J11: =R11 -> 0.16666667 | M11: =IF(OR(K11="U",K11="K"),J11,"0:00") -> 0:00 | N11: =IF(M11<>"0:00",J11,"0:00") -> 0:00 | O11: =IF(K11="0,5 U","03:51","0:00") -> 0:00 | R11: =IF(A11="Mo",Januar!$Q$8,IF(A11="Di",Januar!$Q$9,IF(A11="Mi",Januar!$Q$10,IF(A11="Do",Januar!$Q$11,IF(A11="Fr",Januar!$Q$12,Januar!$Q$13))))) -> 0.16666667
A12: Do | B12: 5. | C12: 0.375 | D12: 0.5 | I12: =D12-C12-F12+E12-H12+G12+N12+O12 -> 0.125 | J12: =R12 -> 0.16666667 | M12: =IF(OR(K12="U",K12="K"),J12,"0:00") -> 0:00 | N12: =IF(M12<>"0:00",J12,"0:00") -> 0:00 | O12: =IF(K12="0,5 U","03:51","0:00") -> 0:00 | R12: =IF(A12="Mo",Januar!$Q$8,IF(A12="Di",Januar!$Q$9,IF(A12="Mi",Januar!$Q$10,IF(A12="Do",Januar!$Q$11,IF(A12="Fr",Januar!$Q$12,Januar!$Q$13))))) -> 0.16666667
A13: Fr | B13: 6. | I13: =D13-C13-F13+E13-H13+G13+N13+O13 -> 0 | J13: =R13 -> 0 | M13: =IF(OR(K13="U",K13="K"),J13,"0:00") -> 0:00 | N13: =IF(M13<>"0:00",J13,"0:00") -> 0:00 | O13: =IF(K13="0,5 U","03:51","0:00") -> 0:00 | R13: =IF(A13="Mo",Januar!$Q$8,IF(A13="Di",Januar!$Q$9,IF(A13="Mi",Januar!$Q$10,IF(A13="Do",Januar!$Q$11,IF(A13="Fr",Januar!$Q$12,Januar!$Q$13))))) -> 0
A14: Sa | B14: 7. | I14: =D14-C14-F14+E14-H14+G14+N14+O14 -> 0 | J14: =R14 -> 0 | M14: =IF(OR(K14="U",K14="K"),J14,"0:00") -> 0:00 | N14: =IF(M14<>"0:00",J14,"0:00") -> 0:00 | O14: =IF(K14="0,5 U","03:51","0:00") -> 0:00 | R14: =IF(A14="Mo",Januar!$Q$8,IF(A14="Di",Januar!$Q$9,IF(A14="Mi",Januar!$Q$10,IF(A14="Do",Januar!$Q$11,IF(A14="Fr",Januar!$Q$12,Januar!$Q$13))))) -> 0
A15: So | B15: 8. | I15: =D15-C15-F15+E15-H15+G15+N15+O15 -> 0 | J15: =R15 -> 0 | M15: =IF(OR(K15="U",K15="K"),J15,"0:00") -> 0:00 | N15: =IF(M15<>"0:00",J15,"0:00") -> 0:00 | O15: =IF(K15="0,5 U","03:51","0:00") -> 0:00 | R15: =IF(A15="Mo",Januar!$Q$8,IF(A15="Di",Januar!$Q$9,IF(A15="Mi",Januar!$Q$10,IF(A15="Do",Januar!$Q$11,IF(A15="Fr",Januar!$Q$12,Januar!$Q$13))))) -> 0
A16: Mo | B16: 9. | C16: 0.35416667 | D16: 0.51041667 | I16: =D16-C16-F16+E16-H16+G16+N16+O16 -> 0.15625 | J16: =R16 -> 0.16666667 | M16: =IF(OR(K16="U",K16="K"),J16,"0:00") -> 0:00 | N16: =IF(M16<>"0:00",J16,"0:00") -> 0:00 | O16: =IF(K16="0,5 U","03:51","0:00") -> 0:00 | R16: =IF(A16="Mo",Januar!$Q$8,IF(A16="Di",Januar!$Q$9,IF(A16="Mi",Januar!$Q$10,IF(A16="Do",Januar!$Q$11,IF(A16="Fr",Januar!$Q$12,Januar!$Q$13))))) -> 0.16666667
A17: Di | B17: 10. | C17: 0.38541667 | D17: 0.66666667 | E17: 0.51041667 | F17: 0.53125 | I17: =D17-C17-F17+E17-H17+G17+N17+O17 -> 0.26041667 | J17: =R17 -> 0.16666667 | M17: =IF(OR(K17="U",K17="K"),J17,"0:00") -> 0:00 | N17: =IF(M17<>"0:00",J17,"0:00") -> 0:00 | O17: =IF(K17="0,5 U","03:51","0:00") -> 0:00 | R17: =IF(A17="Mo",Januar!$Q$8,IF(A17="Di",Januar!$Q$9,IF(A17="Mi",Januar!$Q$10,IF(A17="Do",Januar!$Q$11,IF(A17="Fr",Januar!$Q$12,Januar!$Q$13))))) -> 0.16666667
A18: Mi | B18: 11. | C18: 0.38541667 | D18: 0.51041667 | I18: =D18-C18-F18+E18-H18+G18+N18+O18 -> 0.125 | J18: =R18 -> 0.16666667 | M18: =IF(OR(K18="U",K18="K"),J18,"0:00") -> 0:00 | N18: =IF(M18<>"0:00",J18,"0:00") -> 0:00 | O18: =IF(K18="0,5 U","03:51","0:00") -> 0:00 | R18: =IF(A18="Mo",Januar!$Q$8,IF(A18="Di",Januar!$Q$9,IF(A18="Mi",Januar!$Q$10,IF(A18="Do",Januar!$Q$11,IF(A18="Fr",Januar!$Q$12,Januar!$Q$13))))) -> 0.16666667
A19: Do | B19: 12. | C19: 0.375 | D19: 0.5 | I19: =D19-C19-F19+E19-H19+G19+N19+O19 -> 0.125 | J19: =R19 -> 0.16666667 | M19: =IF(OR(K19="U",K19="K"),J19,"0:00") -> 0:00 | N19: =IF(M19<>"0:00",J19,"0:00") -> 0:00 | O19: =IF(K19="0,5 U","03:51","0:00") -> 0:00 | R19: =IF(A19="Mo",Januar!$Q$8,IF(A19="Di",Januar!$Q$9,IF(A19="Mi",Januar!$Q$10,IF(A19="Do",Januar!$Q$11,IF(A19="Fr",Januar!$Q$12,Januar!$Q$13))))) -> 0.16666667
A20: Fr | B20: 13. | I20: =D20-C20-F20+E20-H20+G20+N20+O20 -> 0 | J20: =R20 -> 0 | M20: =IF(OR(K20="U",K20="K"),J20,"0:00") -> 0:00 | N20: =IF(M20<>"0:00",J20,"0:00") -> 0:00 | O20: =IF(K20="0,5 U","03:51","0:00") -> 0:00 | R20: =IF(A20="Mo",Januar!$Q$8,IF(A20="Di",Januar!$Q$9,IF(A20="Mi",Januar!$Q$10,IF(A20="Do",Januar!$Q$11,IF(A20="Fr",Januar!$Q$12,Januar!$Q$13))))) -> 0
A21: Sa | B21: 14. | I21: =D21-C21-F21+E21-H21+G21+N21+O21 -> 0 | J21: =R21 -> 0 | M21: =IF(OR(K21="U",K21="K"),J21,"0:00") -> 0:00 | N21: =IF(M21<>"0:00",J21,"0:00") -> 0:00 | O21: =IF(K21="0,5 U","03:51","0:00") -> 0:00 | R21: =IF(A21="Mo",Januar!$Q$8,IF(A21="Di",Januar!$Q$9,IF(A21="Mi",Januar!$Q$10,IF(A21="Do",Januar!$Q$11,IF(A21="Fr",Januar!$Q$12,Januar!$Q$13))))) -> 0
A22: So | B22: 15. | I22: =D22-C22-F22+E22-H22+G22+N22+O22 -> 0 | J22: =R22 -> 0 | M22: =IF(OR(K22="U",K22="K"),J22,"0:00") -> 0:00 | N22: =IF(M22<>"0:00",J22,"0:00") -> 0:00 | O22: =IF(K22="0,5 U","03:51","0:00") -> 0:00 | R22: =IF(A22="Mo",Januar!$Q$8,IF(A22="Di",Januar!$Q$9,IF(A22="Mi",Januar!$Q$10,IF(A22="Do",Januar!$Q$11,IF(A22="Fr",Januar!$Q$12,Januar!$Q$13))))) -> 0
A23: Mo | B23: 16. | C23: 0.35416667 | D23: 0.51041667 | I23: =D23-C23-F23+E23-H23+G23+N23+O23 -> 0.15625 | J23: =R23 -> 0.16666667 | M23: =IF(OR(K23="U",K23="K"),J23,"0:00") -> 0:00 | N23: =IF(M23<>"0:00",J23,"0:00") -> 0:00 | O23: =IF(K23="0,5 U","03:51","0:00") -> 0:00 | R23: =IF(A23="Mo",Januar!$Q$8,IF(A23="Di",Januar!$Q$9,IF(A23="Mi",Januar!$Q$10,IF(A23="Do",Januar!$Q$11,IF(A23="Fr",Januar!$Q$12,Januar!$Q$13))))) -> 0.16666667
A24: Di | B24: 17. | C24: 0.38541667 | D24: 0.66666667 | E24: 0.51041667 | F24: 0.53125 | I24: =D24-C24-F24+E24-H24+G24+N24+O24 -> 0.26041667 | J24: =R24 -> 0.16666667 | M24: =IF(OR(K24="U",K24="K"),J24,"0:00") -> 0:00 | N24: =IF(M24<>"0:00",J24,"0:00") -> 0:00 | O24: =IF(K24="0,5 U","03:51","0:00") -> 0:00 | R24: =IF(A24="Mo",Januar!$Q$8,IF(A24="Di",Januar!$Q$9,IF(A24="Mi",Januar!$Q$10,IF(A24="Do",Januar!$Q$11,IF(A24="Fr",Januar!$Q$12,Januar!$Q$13))))) -> 0.16666667
A25: Mi | B25: 18. | C25: 0.38541667 | D25: 0.51041667 | I25: =D25-C25-F25+E25-H25+G25+N25+O25 -> 0.125 | J25: =R25 -> 0.16666667 | M25: =IF(OR(K25="U",K25="K"),J25,"0:00") -> 0:00 | N25: =IF(M25<>"0:00",J25,"0:00") -> 0:00 | O25: =IF(K25="0,5 U","03:51","0:00") -> 0:00 | R25: =IF(A25="Mo",Januar!$Q$8,IF(A25="Di",Januar!$Q$9,IF(A25="Mi",Januar!$Q$10,IF(A25="Do",Januar!$Q$11,IF(A25="Fr",Januar!$Q$12,Januar!$Q$13))))) -> 0.16666667
A26: Do | B26: 19. | C26: 0.375 | D26: 0.5 | I26: =D26-C26-F26+E26-H26+G26+N26+O26 -> 0.125 | J26: =R26 -> 0.16666667 | M26: =IF(OR(K26="U",K26="K"),J26,"0:00") -> 0:00 | N26: =IF(M26<>"0:00",J26,"0:00") -> 0:00 | O26: =IF(K26="0,5 U","03:51","0:00") -> 0:00 | R26: =IF(A26="Mo",Januar!$Q$8,IF(A26="Di",Januar!$Q$9,IF(A26="Mi",Januar!$Q$10,IF(A26="Do",Januar!$Q$11,IF(A26="Fr",Januar!$Q$12,Januar!$Q$13))))) -> 0.16666667
A27: Fr | B27: 20. | I27: =D27-C27-F27+E27-H27+G27+N27+O27 -> 0 | J27: =R27 -> 0 | M27: =IF(OR(K27="U",K27="K"),J27,"0:00") -> 0:00 | N27: =IF(M27<>"0:00",J27,"0:00") -> 0:00 | O27: =IF(K27="0,5 U","03:51","0:00") -> 0:00 | R27: =IF(A27="Mo",Januar!$Q$8,IF(A27="Di",Januar!$Q$9,IF(A27="Mi",Januar!$Q$10,IF(A27="Do",Januar!$Q$11,IF(A27="Fr",Januar!$Q$12,Januar!$Q$13))))) -> 0
A28: Sa | B28: 21. | I28: =D28-C28-F28+E28-H28+G28+N28+O28 -> 0 | J28: =R28 -> 0 | M28: =IF(OR(K28="U",K28="K"),J28,"0:00") -> 0:00 | N28: =IF(M28<>"0:00",J28,"0:00") -> 0:00 | O28: =IF(K28="0,5 U","03:51","0:00") -> 0:00 | R28: =IF(A28="Mo",Januar!$Q$8,IF(A28="Di",Januar!$Q$9,IF(A28="Mi",Januar!$Q$10,IF(A28="Do",Januar!$Q$11,IF(A28="Fr",Januar!$Q$12,Januar!$Q$13))))) -> 0
A29: So | B29: 22. | I29: =D29-C29-F29+E29-H29+G29+N29+O29 -> 0 | J29: =R29 -> 0 | M29: =IF(OR(K29="U",K29="K"),J29,"0:00") -> 0:00 | N29: =IF(M29<>"0:00",J29,"0:00") -> 0:00 | O29: =IF(K29="0,5 U","03:51","0:00") -> 0:00 | R29: =IF(A29="Mo",Januar!$Q$8,IF(A29="Di",Januar!$Q$9,IF(A29="Mi",Januar!$Q$10,IF(A29="Do",Januar!$Q$11,IF(A29="Fr",Januar!$Q$12,Januar!$Q$13))))) -> 0
A30: Mo | B30: 23. | C30: 0.35416667 | D30: 0.51041667 | I30: =D30-C30-F30+E30-H30+G30+N30+O30 -> 0.15625 | J30: =R30 -> 0.16666667 | M30: =IF(OR(K30="U",K30="K"),J30,"0:00") -> 0:00 | N30: =IF(M30<>"0:00",J30,"0:00") -> 0:00 | O30: =IF(K30="0,5 U","03:51","0:00") -> 0:00 | R30: =IF(A30="Mo",Januar!$Q$8,IF(A30="Di",Januar!$Q$9,IF(A30="Mi",Januar!$Q$10,IF(A30="Do",Januar!$Q$11,IF(A30="Fr",Januar!$Q$12,Januar!$Q$13))))) -> 0.16666667
A31: Di | B31: 24. | C31: 0.38541667 | D31: 0.66666667 | E31: 0.51041667 | F31: 0.53125 | I31: =D31-C31-F31+E31-H31+G31+N31+O31 -> 0.26041667 | J31: =R31 -> 0.16666667 | M31: =IF(OR(K31="U",K31="K"),J31,"0:00") -> 0:00 | N31: =IF(M31<>"0:00",J31,"0:00") -> 0:00 | O31: =IF(K31="0,5 U","03:51","0:00") -> 0:00 | R31: =IF(A31="Mo",Januar!$Q$8,IF(A31="Di",Januar!$Q$9,IF(A31="Mi",Januar!$Q$10,IF(A31="Do",Januar!$Q$11,IF(A31="Fr",Januar!$Q$12,Januar!$Q$13))))) -> 0.16666667
A32: Mi | B32: 25. | C32: 0.38541667 | D32: 0.51041667 | I32: =D32-C32-F32+E32-H32+G32+N32+O32 -> 0.125 | J32: =R32 -> 0.16666667 | M32: =IF(OR(K32="U",K32="K"),J32,"0:00") -> 0:00 | N32: =IF(M32<>"0:00",J32,"0:00") -> 0:00 | O32: =IF(K32="0,5 U","03:51","0:00") -> 0:00 | R32: =IF(A32="Mo",Januar!$Q$8,IF(A32="Di",Januar!$Q$9,IF(A32="Mi",Januar!$Q$10,IF(A32="Do",Januar!$Q$11,IF(A32="Fr",Januar!$Q$12,Januar!$Q$13))))) -> 0.16666667
A33: Do | B33: 26. | C33: 0.375 | D33: 0.5 | I33: =D33-C33-F33+E33-H33+G33+N33+O33 -> 0.125 | J33: =R33 -> 0.16666667 | M33: =IF(OR(K33="U",K33="K"),J33,"0:00") -> 0:00 | N33: =IF(M33<>"0:00",J33,"0:00") -> 0:00 | O33: =IF(K33="0,5 U","03:51","0:00") -> 0:00 | R33: =IF(A33="Mo",Januar!$Q$8,IF(A33="Di",Januar!$Q$9,IF(A33="Mi",Januar!$Q$10,IF(A33="Do",Januar!$Q$11,IF(A33="Fr",Januar!$Q$12,Januar!$Q$13))))) -> 0.16666667
A34: Fr | B34: 27. | I34: =D34-C34-F34+E34-H34+G34+N34+O34 -> 0 | J34: =R34 -> 0 | M34: =IF(OR(K34="U",K34="K"),J34,"0:00") -> 0:00 | N34: =IF(M34<>"0:00",J34,"0:00") -> 0:00 | O34: =IF(K34="0,5 U","03:51","0:00") -> 0:00 | R34: =IF(A34="Mo",Januar!$Q$8,IF(A34="Di",Januar!$Q$9,IF(A34="Mi",Januar!$Q$10,IF(A34="Do",Januar!$Q$11,IF(A34="Fr",Januar!$Q$12,Januar!$Q$13))))) -> 0
A35: Sa | B35: 28. | I35: =D35-C35-F35+E35-H35+G35+N35+O35 -> 0 | J35: =R35 -> 0 | M35: =IF(OR(K35="U",K35="K"),J35,"0:00") -> 0:00 | N35: =IF(M35<>"0:00",J35,"0:00") -> 0:00 | O35: =IF(K35="0,5 U","03:51","0:00") -> 0:00 | R35: =IF(A35="Mo",Januar!$Q$8,IF(A35="Di",Januar!$Q$9,IF(A35="Mi",Januar!$Q$10,IF(A35="Do",Januar!$Q$11,IF(A35="Fr",Januar!$Q$12,Januar!$Q$13))))) -> 0
A36: So | B36: 29. | I36: =D36-C36-F36+E36-H36+G36+N36+O36 -> 0 | J36: 0 | M36: =IF(OR(K36="U",K36="K"),J36,"0:00") -> 0:00 | N36: =IF(M36<>"0:00",J36,"0:00") -> 0:00 | O36: =IF(K36="0,5 U","03:51","0:00") -> 0:00 | R36: =IF(A36="Mo",Januar!$Q$8,IF(A36="Di",Januar!$Q$9,IF(A36="Mi",Januar!$Q$10,IF(A36="Do",Januar!$Q$11,IF(A36="Fr",Januar!$Q$12,Januar!$Q$13))))) -> 0
A37: Mo | B37: 30. | C37: 0.35416667 | D37: 0.51041667 | I37: =D37-C37-F37+E37-H37+G37+N37+O37 -> 0.15625 | J37: =R37 -> 0.16666667 | M37: =IF(OR(K37="U",K37="K"),J37,"0:00") -> 0:00 | N37: =IF(M37<>"0:00",J37,"0:00") -> 0:00 | O37: =IF(K37="0,5 U","03:51","0:00") -> 0:00 | R37: =IF(A37="Mo",Januar!$Q$8,IF(A37="Di",Januar!$Q$9,IF(A37="Mi",Januar!$Q$10,IF(A37="Do",Januar!$Q$11,IF(A37="Fr",Januar!$Q$12,Januar!$Q$13))))) -> 0.16666667
A38: Di | B38: 31. | C38: 0.38541667 | D38: 0.66666667 | E38: 0.51041667 | F38: 0.53125 | I38: =D38-C38-F38+E38-H38+G38+N38+O38 -> 0.26041667 | J38: =R38 -> 0.16666667 | M38: =IF(OR(K38="U",K38="K"),J38,"0:00") -> 0:00 | N38: =IF(M38<>"0:00",J38,"0:00") -> 0:00 | O38: =IF(K38="0,5 U","03:51","0:00") -> 0:00 | R38: =IF(A38="Mo",Januar!$Q$8,IF(A38="Di",Januar!$Q$9,IF(A38="Mi",Januar!$Q$10,IF(A38="Do",Januar!$Q$11,IF(A38="Fr",Januar!$Q$12,Januar!$Q$13))))) -> 0.16666667
I39: Ist | J39: Soll
E40: monatliche Arbeitstunden | I40: =SUM(I8:I38) -> 3.0833333 | J40: =SUM(J8:J38) -> 3
C43: Ist-Arbeitsstunden | G43: =I40 -> 3.0833333 | J43: Erholungsurlaub
J44: =Januar!J44 -> Resturlaub 2025 | L44: =Januar!L44 -> 4
C45: zzgl. Zeitguthaben Vormonat | G45: =Februar!G49 -> 0.125 | J45: =Januar!J45 -> Jahresurlaub 2026 | L45: =Januar!L45 -> 24
...

Sheet April
B1: =Januar!B1 -> Arbeitszeiterfassung 2026
B4: Name: | C4: =Januar!C4 -> Andrea Keller-Brockmann | K4: Monat: | L4: April
B6: Datum | C6: Arbeitsphase | E6: Unterbrechungen | I6: Arbeitsstunden | K6: Anmerkungen
C7: Beginn | D7: Ende | E7: Beginn | F7: Ende | G7: Beginn | H7: Ende | I7: Ist | J7: Soll | K7: Anm. U/K
A8: Mi | B8: 1. | C8: 0.38541667 | D8: 0.51041667 | I8: =D8-C8-F8+E8-H8+G8+N8+O8 -> 0.125 | J8: =R8 -> 0.16666667 | M8: =IF(OR(K8="U",K8="K"),J8,"0:00") -> 0:00 | N8: =IF(M8<>"0:00",J8,"0:00") -> 0:00 | O8: =IF(K8="0,5 U","03:51","0:00") -> 0:00 | R8: =IF(A8="Mo",Januar!$Q$8,IF(A8="Di",Januar!$Q$9,IF(A8="Mi",Januar!$Q$10,IF(A8="Do",Januar!$Q$11,IF(A8="Fr",Januar!$Q$12,Januar!$Q$13))))) -> 0.16666667
A9: Do | B9: 2. | C9: 0.375 | D9: 0.5 | I9: =D9-C9-F9+E9-H9+G9+N9+O9 -> 0.125 | J9: =R9 -> 0.16666667 | M9: =IF(OR(K9="U",K9="K"),J9,"0:00") -> 0:00 | N9: =IF(M9<>"0:00",J9,"0:00") -> 0:00 | O9: =IF(K9="0,5 U","03:51","0:00") -> 0:00 | R9: =IF(A9="Mo",Januar!$Q$8,IF(A9="Di",Januar!$Q$9,IF(A9="Mi",Januar!$Q$10,IF(A9="Do",Januar!$Q$11,IF(A9="Fr",Januar!$Q$12,Januar!$Q$13))))) -> 0.16666667
A10: Fr | B10: 3. | I10: =D10-C10-F10+E10-H10+G10+N10+O10 -> 0 | J10: 0 | M10: =IF(OR(K10="U",K10="K"),J10,"0:00") -> 0:00 | N10: =IF(M10<>"0:00",J10,"0:00") -> 0:00 | O10: =IF(K10="0,5 U","03:51","0:00") -> 0:00 | R10: =IF(A10="Mo",Januar!$Q$8,IF(A10="Di",Januar!$Q$9,IF(A10="Mi",Januar!$Q$10,IF(A10="Do",Januar!$Q$11,IF(A10="Fr",Januar!$Q$12,Januar!$Q$13))))) -> 0
A11: Sa | B11: 4. | I11: =D11-C11-F11+E11-H11+G11+N11+O11 -> 0 | J11: =R11 -> 0 | M11: =IF(OR(K11="U",K11="K"),J11,"0:00") -> 0:00 | N11: =IF(M11<>"0:00",J11,"0:00") -> 0:00 | O11: =IF(K11="0,5 U","03:51","0:00") -> 0:00 | R11: =IF(A11="Mo",Januar!$Q$8,IF(A11="Di",Januar!$Q$9,IF(A11="Mi",Januar!$Q$10,IF(A11="Do",Januar!$Q$11,IF(A11="Fr",Januar!$Q$12,Januar!$Q$13))))) -> 0
A12: So | B12: 5. | I12: =D12-C12-F12+E12-H12+G12+N12+O12 -> 0 | J12: =R12 -> 0 | M12: =IF(OR(K12="U",K12="K"),J12,"0:00") -> 0:00 | N12: =IF(M12<>"0:00",J12,"0:00") -> 0:00 | O12: =IF(K12="0,5 U","03:51","0:00") -> 0:00 | R12: =IF(A12="Mo",Januar!$Q$8,IF(A12="Di",Januar!$Q$9,IF(A12="Mi",Januar!$Q$10,IF(A12="Do",Januar!$Q$11,IF(A12="Fr",Januar!$Q$12,Januar!$Q$13))))) -> 0
A13: Mo | B13: 6. | C13: 0.35416667 | D13: 0.51041667 | I13: =D13-C13-F13+E13-H13+G13+N13+O13 -> 0.15625 | J13: 0 | M13: =IF(OR(K13="U",K13="K"),J13,"0:00") -> 0:00 | N13: =IF(M13<>"0:00",J13,"0:00") -> 0:00 | O13: =IF(K13="0,5 U","03:51","0:00") -> 0:00 | R13: =IF(A13="Mo",Januar!$Q$8,IF(A13="Di",Januar!$Q$9,IF(A13="Mi",Januar!$Q$10,IF(A13="Do",Januar!$Q$11,IF(A13="Fr",Januar!$Q$12,Januar!$Q$13))))) -> 0.16666667
A14: Di | B14: 7. | C14: 0.38541667 | D14: 0.66666667 | E14: 0.51041667 | F14: 0.53125 | I14: =D14-C14-F14+E14-H14+G14+N14+O14 -> 0.26041667 | J14: =R14 -> 0.16666667 | M14: =IF(OR(K14="U",K14="K"),J14,"0:00") -> 0:00 | N14: =IF(M14<>"0:00",J14,"0:00") -> 0:00 | O14: =IF(K14="0,5 U","03:51","0:00") -> 0:00 | R14: =IF(A14="Mo",Januar!$Q$8,IF(A14="Di",Januar!$Q$9,IF(A14="Mi",Januar!$Q$10,IF(A14="Do",Januar!$Q$11,IF(A14="Fr",Januar!$Q$12,Januar!$Q$13))))) -> 0.16666667
A15: Mi | B15: 8. | C15: 0.38541667 | D15: 0.51041667 | I15: =D15-C15-F15+E15-H15+G15+N15+O15 -> 0.125 | J15: =R15 -> 0.16666667 | M15: =IF(OR(K15="U",K15="K"),J15,"0:00") -> 0:00 | N15: =IF(M15<>"0:00",J15,"0:00") -> 0:00 | O15: =IF(K15="0,5 U","03:51","0:00") -> 0:00 | R15: =IF(A15="Mo",Januar!$Q$8,IF(A15="Di",Januar!$Q$9,IF(A15="Mi",Januar!$Q$10,IF(A15="Do",Januar!$Q$11,IF(A15="Fr",Januar!$Q$12,Januar!$Q$13))))) -> 0.16666667
A16: Do | B16: 9. | C16: 0.375 | D16: 0.5 | I16: =D16-C16-F16+E16-H16+G16+N16+O16 -> 0.125 | J16: =R16 -> 0.16666667 | M16: =IF(OR(K16="U",K16="K"),J16,"0:00") -> 0:00 | N16: =IF(M16<>"0:00",J16,"0:00") -> 0:00 | O16: =IF(K16="0,5 U","03:51","0:00") -> 0:00 | R16: =IF(A16="Mo",Januar!$Q$8,IF(A16="Di",Januar!$Q$9,IF(A16="Mi",Januar!$Q$10,IF(A16="Do",Januar!$Q$11,IF(A16="Fr",Januar!$Q$12,Januar!$Q$13))))) -> 0.16666667
A17: Fr | B17: 10. | I17: =D17-C17-F17+E17-H17+G17+N17+O17 -> 0 | J17: =R17 -> 0 | M17: =IF(OR(K17="U",K17="K"),J17,"0:00") -> 0:00 | N17: =IF(M17<>"0:00",J17,"0:00") -> 0:00 | O17: =IF(K17="0,5 U","03:51","0:00") -> 0:00 | R17: =IF(A17="Mo",Januar!$Q$8,IF(A17="Di",Januar!$Q$9,IF(A17="Mi",Januar!$Q$10,IF(A17="Do",Januar!$Q$11,IF(A17="Fr",Januar!$Q$12,Januar!$Q$13))))) -> 0
A18: Sa | B18: 11. | I18: =D18-C18-F18+E18-H18+G18+N18+O18 -> 0 | J18: =R18 -> 0 | M18: =IF(OR(K18="U",K18="K"),J18,"0:00") -> 0:00 | N18: =IF(M18<>"0:00",J18,"0:00") -> 0:00 | O18: =IF(K18="0,5 U","03:51","0:00") -> 0:00 | R18: =IF(A18="Mo",Januar!$Q$8,IF(A18="Di",Januar!$Q$9,IF(A18="Mi",Januar!$Q$10,IF(A18="Do",Januar!$Q$11,IF(A18="Fr",Januar!$Q$12,Januar!$Q$13))))) -> 0
A19: So | B19: 12. | I19: =D19-C19-F19+E19-H19+G19+N19+O19 -> 0 | J19: =R19 -> 0 | M19: =IF(OR(K19="U",K19="K"),J19,"0:00") -> 0:00 | N19: =IF(M19<>"0:00",J19,"0:00") -> 0:00 | O19: =IF(K19="0,5 U","03:51","0:00") -> 0:00 | R19: =IF(A19="Mo",Januar!$Q$8,IF(A19="Di",Januar!$Q$9,IF(A19="Mi",Januar!$Q$10,IF(A19="Do",Januar!$Q$11,IF(A19="Fr",Januar!$Q$12,Januar!$Q$13))))) -> 0
A20: Mo | B20: 13. | C20: 0.35416667 | D20: 0.51041667 | I20: =D20-C20-F20+E20-H20+G20+N20+O20 -> 0.15625 | J20: =R20 -> 0.16666667 | M20: =IF(OR(K20="U",K20="K"),J20,"0:00") -> 0:00 | N20: =IF(M20<>"0:00",J20,"0:00") -> 0:00 | O20: =IF(K20="0,5 U","03:51","0:00") -> 0:00 | R20: =IF(A20="Mo",Januar!$Q$8,IF(A20="Di",Januar!$Q$9,IF(A20="Mi",Januar!$Q$10,IF(A20="Do",Januar!$Q$11,IF(A20="Fr",Januar!$Q$12,Januar!$Q$13))))) -> 0.16666667
A21: Di | B21: 14. | C21: 0.38541667 | D21: 0.66666667 | E21: 0.51041667 | F21: 0.53125 | I21: =D21-C21-F21+E21-H21+G21+N21+O21 -> 0.26041667 | J21: =R21 -> 0.16666667 | M21: =IF(OR(K21="U",K21="K"),J21,"0:00") -> 0:00 | N21: =IF(M21<>"0:00",J21,"0:00") -> 0:00 | O21: =IF(K21="0,5 U","03:51","0:00") -> 0:00 | R21: =IF(A21="Mo",Januar!$Q$8,IF(A21="Di",Januar!$Q$9,IF(A21="Mi",Januar!$Q$10,IF(A21="Do",Januar!$Q$11,IF(A21="Fr",Januar!$Q$12,Januar!$Q$13))))) -> 0.16666667
A22: Mi | B22: 15. | C22: 0.38541667 | D22: 0.51041667 | I22: =D22-C22-F22+E22-H22+G22+N22+O22 -> 0.125 | J22: =R22 -> 0.16666667 | M22: =IF(OR(K22="U",K22="K"),J22,"0:00") -> 0:00 | N22: =IF(M22<>"0:00",J22,"0:00") -> 0:00 | O22: =IF(K22="0,5 U","03:51","0:00") -> 0:00 | R22: =IF(A22="Mo",Januar!$Q$8,IF(A22="Di",Januar!$Q$9,IF(A22="Mi",Januar!$Q$10,IF(A22="Do",Januar!$Q$11,IF(A22="Fr",Januar!$Q$12,Januar!$Q$13))))) -> 0.16666667
A23: Do | B23: 16. | C23: 0.375 | D23: 0.5 | I23: =D23-C23-F23+E23-H23+G23+N23+O23 -> 0.125 | J23: =R23 -> 0.16666667 | M23: =IF(OR(K23="U",K23="K"),J23,"0:00") -> 0:00 | N23: =IF(M23<>"0:00",J23,"0:00") -> 0:00 | O23: =IF(K23="0,5 U","03:51","0:00") -> 0:00 | R23: =IF(A23="Mo",Januar!$Q$8,IF(A23="Di",Januar!$Q$9,IF(A23="Mi",Januar!$Q$10,IF(A23="Do",Januar!$Q$11,IF(A23="Fr",Januar!$Q$12,Januar!$Q$13))))) -> 0.16666667
A24: Fr | B24: 17. | I24: =D24-C24-F24+E24-H24+G24+N24+O24 -> 0 | J24: =R24 -> 0 | M24: =IF(OR(K24="U",K24="K"),J24,"0:00") -> 0:00 | N24: =IF(M24<>"0:00",J24,"0:00") -> 0:00 | O24: =IF(K24="0,5 U","03:51","0:00") -> 0:00 | R24: =IF(A24="Mo",Januar!$Q$8,IF(A24="Di",Januar!$Q$9,IF(A24="Mi",Januar!$Q$10,IF(A24="Do",Januar!$Q$11,IF(A24="Fr",Januar!$Q$12,Januar!$Q$13))))) -> 0
A25: Sa | B25: 18. | I25: =D25-C25-F25+E25-H25+G25+N25+O25 -> 0 | J25: 0 | M25: =IF(OR(K25="U",K25="K"),J25,"0:00") -> 0:00 | N25: =IF(M25<>"0:00",J25,"0:00") -> 0:00 | O25: =IF(K25="0,5 U","03:51","0:00") -> 0:00 | R25: =IF(A25="Mo",Januar!$Q$8,IF(A25="Di",Januar!$Q$9,IF(A25="Mi",Januar!$Q$10,IF(A25="Do",Januar!$Q$11,IF(A25="Fr",Januar!$Q$12,Januar!$Q$13))))) -> 0
A26: So | B26: 19. | I26: =D26-C26-F26+E26-H26+G26+N26+O26 -> 0 | J26: =R26 -> 0 | M26: =IF(OR(K26="U",K26="K"),J26,"0:00") -> 0:00 | N26: =IF(M26<>"0:00",J26,"0:00") -> 0:00 | O26: =IF(K26="0,5 U","03:51","0:00") -> 0:00 | R26: =IF(A26="Mo",Januar!$Q$8,IF(A26="Di",Januar!$Q$9,IF(A26="Mi",Januar!$Q$10,IF(A26="Do",Januar!$Q$11,IF(A26="Fr",Januar!$Q$12,Januar!$Q$13))))) -> 0
A27: Mo | B27: 20. | C27: 0.35416667 | D27: 0.51041667 | I27: =D27-C27-F27+E27-H27+G27+N27+O27 -> 0.15625 | J27: =R27 -> 0.16666667 | M27: =IF(OR(K27="U",K27="K"),J27,"0:00") -> 0:00 | N27: =IF(M27<>"0:00",J27,"0:00") -> 0:00 | O27: =IF(K27="0,5 U","03:51","0:00") -> 0:00 | R27: =IF(A27="Mo",Januar!$Q$8,IF(A27="Di",Januar!$Q$9,IF(A27="Mi",Januar!$Q$10,IF(A27="Do",Januar!$Q$11,IF(A27="Fr",Januar!$Q$12,Januar!$Q$13))))) -> 0.16666667
A28: Di | B28: 21. | C28: 0.38541667 | D28: 0.66666667 | E28: 0.51041667 | F28: 0.53125 | I28: =D28-C28-F28+E28-H28+G28+N28+O28 -> 0.26041667 | J28: 0.275 | M28: =IF(OR(K28="U",K28="K"),J28,"0:00") -> 0:00 | N28: =IF(M28<>"0:00",J28,"0:00") -> 0:00 | O28: =IF(K28="0,5 U","03:51","0:00") -> 0:00 | R28: =IF(A28="Mo",Januar!$Q$8,IF(A28="Di",Januar!$Q$9,IF(A28="Mi",Januar!$Q$10,IF(A28="Do",Januar!$Q$11,IF(A28="Fr",Januar!$Q$12,Januar!$Q$13))))) -> 0.16666667
A29: Mi | B29: 22. | C29: 0.38541667 | D29: 0.51041667 | I29: =D29-C29-F29+E29-H29+G29+N29+O29 -> 0.125 | J29: =R29 -> 0.16666667 | M29: =IF(OR(K29="U",K29="K"),J29,"0:00") -> 0:00 | N29: =IF(M29<>"0:00",J29,"0:00") -> 0:00 | O29: =IF(K29="0,5 U","03:51","0:00") -> 0:00 | R29: =IF(A29="Mo",Januar!$Q$8,IF(A29="Di",Januar!$Q$9,IF(A29="Mi",Januar!$Q$10,IF(A29="Do",Januar!$Q$11,IF(A29="Fr",Januar!$Q$12,Januar!$Q$13))))) -> 0.16666667
A30: Do | B30: 23. | C30: 0.375 | D30: 0.5 | I30: =D30-C30-F30+E30-H30+G30+N30+O30 -> 0.125 | J30: =R30 -> 0.16666667 | M30: =IF(OR(K30="U",K30="K"),J30,"0:00") -> 0:00 | N30: =IF(M30<>"0:00",J30,"0:00") -> 0:00 | O30: =IF(K30="0,5 U","03:51","0:00") -> 0:00 | R30: =IF(A30="Mo",Januar!$Q$8,IF(A30="Di",Januar!$Q$9,IF(A30="Mi",Januar!$Q$10,IF(A30="Do",Januar!$Q$11,IF(A30="Fr",Januar!$Q$12,Januar!$Q$13))))) -> 0.16666667
A31: Fr | B31: 24. | I31: =D31-C31-F31+E31-H31+G31+N31+O31 -> 0 | J31: =R31 -> 0 | M31: =IF(OR(K31="U",K31="K"),J31,"0:00") -> 0:00 | N31: =IF(M31<>"0:00",J31,"0:00") -> 0:00 | O31: =IF(K31="0,5 U","03:51","0:00") -> 0:00 | R31: =IF(A31="Mo",Januar!$Q$8,IF(A31="Di",Januar!$Q$9,IF(A31="Mi",Januar!$Q$10,IF(A31="Do",Januar!$Q$11,IF(A31="Fr",Januar!$Q$12,Januar!$Q$13))))) -> 0
A32: Sa | B32: 25. | I32: =D32-C32-F32+E32-H32+G32+N32+O32 -> 0 | J32: =R32 -> 0 | M32: =IF(OR(K32="U",K32="K"),J32,"0:00") -> 0:00 | N32: =IF(M32<>"0:00",J32,"0:00") -> 0:00 | O32: =IF(K32="0,5 U","03:51","0:00") -> 0:00 | R32: =IF(A32="Mo",Januar!$Q$8,IF(A32="Di",Januar!$Q$9,IF(A32="Mi",Januar!$Q$10,IF(A32="Do",Januar!$Q$11,IF(A32="Fr",Januar!$Q$12,Januar!$Q$13))))) -> 0
A33: So | B33: 26. | I33: =D33-C33-F33+E33-H33+G33+N33+O33 -> 0 | J33: =R33 -> 0 | M33: =IF(OR(K33="U",K33="K"),J33,"0:00") -> 0:00 | N33: =IF(M33<>"0:00",J33,"0:00") -> 0:00 | O33: =IF(K33="0,5 U","03:51","0:00") -> 0:00 | R33: =IF(A33="Mo",Januar!$Q$8,IF(A33="Di",Januar!$Q$9,IF(A33="Mi",Januar!$Q$10,IF(A33="Do",Januar!$Q$11,IF(A33="Fr",Januar!$Q$12,Januar!$Q$13))))) -> 0
A34: Mo | B34: 27. | C34: 0.35416667 | D34: 0.51041667 | I34: =D34-C34-F34+E34-H34+G34+N34+O34 -> 0.15625 | J34: =R34 -> 0.16666667 | M34: =IF(OR(K34="U",K34="K"),J34,"0:00") -> 0:00 | N34: =IF(M34<>"0:00",J34,"0:00") -> 0:00 | O34: =IF(K34="0,5 U","03:51","0:00") -> 0:00 | R34: =IF(A34="Mo",Januar!$Q$8,IF(A34="Di",Januar!$Q$9,IF(A34="Mi",Januar!$Q$10,IF(A34="Do",Januar!$Q$11,IF(A34="Fr",Januar!$Q$12,Januar!$Q$13))))) -> 0.16666667
A35: Di | B35: 28. | C35: 0.38541667 | D35: 0.66666667 | E35: 0.51041667 | F35: 0.53125 | I35: =D35-C35-F35+E35-H35+G35+N35+O35 -> 0.26041667 | J35: =R35 -> 0.16666667 | M35: =IF(OR(K35="U",K35="K"),J35,"0:00") -> 0:00 | N35: =IF(M35<>"0:00",J35,"0:00") -> 0:00 | O35: =IF(K35="0,5 U","03:51","0:00") -> 0:00 | R35: =IF(A35="Mo",Januar!$Q$8,IF(A35="Di",Januar!$Q$9,IF(A35="Mi",Januar!$Q$10,IF(A35="Do",Januar!$Q$11,IF(A35="Fr",Januar!$Q$12,Januar!$Q$13))))) -> 0.16666667
A36: Mi | B36: 29. | C36: 0.38541667 | D36: 0.51041667 | I36: =D36-C36-F36+E36-H36+G36+N36+O36 -> 0.125 | J36: =R36 -> 0.16666667 | M36: =IF(OR(K36="U",K36="K"),J36,"0:00") -> 0:00 | N36: =IF(M36<>"0:00",J36,"0:00") -> 0:00 | O36: =IF(K36="0,5 U","03:51","0:00") -> 0:00 | R36: =IF(A36="Mo",Januar!$Q$8,IF(A36="Di",Januar!$Q$9,IF(A36="Mi",Januar!$Q$10,IF(A36="Do",Januar!$Q$11,IF(A36="Fr",Januar!$Q$12,Januar!$Q$13))))) -> 0.16666667
A37: Do | B37: 30. | C37: 0.375 | D37: 0.5 | I37: =D37-C37-F37+E37-H37+G37+N37+O37 -> 0.125 | J37: =R37 -> 0.16666667 | M37: =IF(OR(K37="U",K37="K"),J37,"0:00") -> 0:00 | N37: =IF(M37<>"0:00",J37,"0:00") -> 0:00 | O37: =IF(K37="0,5 U","03:51","0:00") -> 0:00 | R37: =IF(A37="Mo",Januar!$Q$8,IF(A37="Di",Januar!$Q$9,IF(A37="Mi",Januar!$Q$10,IF(A37="Do",Januar!$Q$11,IF(A37="Fr",Januar!$Q$12,Januar!$Q$13))))) -> 0.16666667
I38: Ist | J38: Soll | R38: =IF(A38="Mo",Januar!$Q$8,IF(A38="Di",Januar!$Q$9,IF(A38="Mi",Januar!$Q$10,IF(A38="Do",Januar!$Q$11,IF(A38="Fr",Januar!$Q$12,Januar!$Q$13))))) -> 0
E39: monatliche Arbeitstunden | I39: =SUM(I8:I37) -> 2.9166667 | J39: =SUM(J8:J37) -> 2.9416667
C43: Ist-Arbeitsstunden | G43: =I39 -> 2.9166667 | J43: Erholungsurlaub
J44: =Januar!J44 -> Resturlaub 2025 | L44: =Januar!L44 -> 4
C45: zzgl. Zeitguthaben Vormonat | G45: =März!G50 -> 0.20833333 | J45: =Januar!J45 -> Jahresurlaub 2026 | L45: =Januar!L45 -> 24
C46: abzgl. Zeitdefizit Vormonat | F46: - | G46: =März!G51 -> 00:00 | J46: =Januar!J46 -> Zusatzurlaub SGB IX | L46: =Januar!L46 -> 0
...

Sheet Mai
B1: =Januar!B1 -> Arbeitszeiterfassung 2026
B4: Name: | C4: =Januar!C4 -> Andrea Keller-Brockmann | K4: Monat: | L4: Mai
B6: Datum | C6: Arbeitsphase | E6: Unterbrechungen | I6: Arbeitsstunden | K6: Anmerkungen
C7: Beginn | D7: Ende | E7: Beginn | F7: Ende | G7: Beginn | H7: Ende | I7: Ist | J7: Soll | K7: Anm. U/K
A8: Fr | B8: 1. | I8: =D8-C8-F8+E8-H8+G8+N8+O8 -> 0 | J8: 0 | M8: =IF(OR(K8="U",K8="K"),J8,"0:00") -> 0:00 | N8: =IF(M8<>"0:00",J8,"0:00") -> 0:00 | O8: =IF(K8="0,5 U","03:51","0:00") -> 0:00 | R8: =IF(A8="Mo",Januar!$Q$8,IF(A8="Di",Januar!$Q$9,IF(A8="Mi",Januar!$Q$10,IF(A8="Do",Januar!$Q$11,IF(A8="Fr",Januar!$Q$12,Januar!$Q$13))))) -> 0
A9: Sa | B9: 2. | I9: =D9-C9-F9+E9-H9+G9+N9+O9 -> 0 | J9: =R9 -> 0 | M9: =IF(OR(K9="U",K9="K"),J9,"0:00") -> 0:00 | N9: =IF(M9<>"0:00",J9,"0:00") -> 0:00 | O9: =IF(K9="0,5 U","03:51","0:00") -> 0:00 | R9: =IF(A9="Mo",Januar!$Q$8,IF(A9="Di",Januar!$Q$9,IF(A9="Mi",Januar!$Q$10,IF(A9="Do",Januar!$Q$11,IF(A9="Fr",Januar!$Q$12,Januar!$Q$13))))) -> 0
A10: So | B10: 3. | I10: =D10-C10-F10+E10-H10+G10+N10+O10 -> 0 | J10: =R10 -> 0 | M10: =IF(OR(K10="U",K10="K"),J10,"0:00") -> 0:00 | N10: =IF(M10<>"0:00",J10,"0:00") -> 0:00 | O10: =IF(K10="0,5 U","03:51","0:00") -> 0:00 | R10: =IF(A10="Mo",Januar!$Q$8,IF(A10="Di",Januar!$Q$9,IF(A10="Mi",Januar!$Q$10,IF(A10="Do",Januar!$Q$11,IF(A10="Fr",Januar!$Q$12,Januar!$Q$13))))) -> 0
A11: Mo | B11: 4. | C11: 0.35416667 | D11: 0.51041667 | I11: =D11-C11-F11+E11-H11+G11+N11+O11 -> 0.15625 | J11: =R11 -> 0.16666667 | M11: =IF(OR(K11="U",K11="K"),J11,"0:00") -> 0:00 | N11: =IF(M11<>"0:00",J11,"0:00") -> 0:00 | O11: =IF(K11="0,5 U","03:51","0:00") -> 0:00 | R11: =IF(A11="Mo",Januar!$Q$8,IF(A11="Di",Januar!$Q$9,IF(A11="Mi",Januar!$Q$10,IF(A11="Do",Januar!$Q$11,IF(A11="Fr",Januar!$Q$12,Januar!$Q$13))))) -> 0.16666667
A12: Di | B12: 5. | C12: 0.38541667 | D12: 0.66666667 | E12: 0.51041667 | F12: 0.53125 | I12: =D12-C12-F12+E12-H12+G12+N12+O12 -> 0.26041667 | J12: 0.25 | M12: =IF(OR(K12="U",K12="K"),J12,"0:00") -> 0:00 | N12: =IF(M12<>"0:00",J12,"0:00") -> 0:00 | O12: =IF(K12="0,5 U","03:51","0:00") -> 0:00 | R12: =IF(A12="Mo",Januar!$Q$8,IF(A12="Di",Januar!$Q$9,IF(A12="Mi",Januar!$Q$10,IF(A12="Do",Januar!$Q$11,IF(A12="Fr",Januar!$Q$12,Januar!$Q$13))))) -> 0.16666667
A13: Mi | B13: 6. | C13: 0.38541667 | D13: 0.51041667 | I13: =D13-C13-F13+E13-H13+G13+N13+O13 -> 0.125 | J13: =R13 -> 0.16666667 | M13: =IF(OR(K13="U",K13="K"),J13,"0:00") -> 0:00 | N13: =IF(M13<>"0:00",J13,"0:00") -> 0:00 | O13: =IF(K13="0,5 U","03:51","0:00") -> 0:00 | R13: =IF(A13="Mo",Januar!$Q$8,IF(A13="Di",Januar!$Q$9,IF(A13="Mi",Januar!$Q$10,IF(A13="Do",Januar!$Q$11,IF(A13="Fr",Januar!$Q$12,Januar!$Q$13))))) -> 0.16666667
A14: Do | B14: 7. | C14: 0.375 | D14: 0.5 | I14: =D14-C14-F14+E14-H14+G14+N14+O14 -> 0.125 | J14: =R14 -> 0.16666667 | M14: =IF(OR(K14="U",K14="K"),J14,"0:00") -> 0:00 | N14: =IF(M14<>"0:00",J14,"0:00") -> 0:00 | O14: =IF(K14="0,5 U","03:51","0:00") -> 0:00 | R14: =IF(A14="Mo",Januar!$Q$8,IF(A14="Di",Januar!$Q$9,IF(A14="Mi",Januar!$Q$10,IF(A14="Do",Januar!$Q$11,IF(A14="Fr",Januar!$Q$12,Januar!$Q$13))))) -> 0.16666667
A15: Fr | B15: 8. | I15: =D15-C15-F15+E15-H15+G15+N15+O15 -> 0 | J15: =R15 -> 0 | M15: =IF(OR(K15="U",K15="K"),J15,"0:00") -> 0:00 | N15: =IF(M15<>"0:00",J15,"0:00") -> 0:00 | O15: =IF(K15="0,5 U","03:51","0:00") -> 0:00 | R15: =IF(A15="Mo",Januar!$Q$8,IF(A15="Di",Januar!$Q$9,IF(A15="Mi",Januar!$Q$10,IF(A15="Do",Januar!$Q$11,IF(A15="Fr",Januar!$Q$12,Januar!$Q$13))))) -> 0
A16: Sa | B16: 9. | I16: =D16-C16-F16+E16-H16+G16+N16+O16 -> 0 | J16: 0 | M16: =IF(OR(K16="U",K16="K"),J16,"0:00") -> 0:00 | N16: =IF(M16<>"0:00",J16,"0:00") -> 0:00 | O16: =IF(K16="0,5 U","03:51","0:00") -> 0:00 | R16: =IF(A16="Mo",Januar!$Q$8,IF(A16="Di",Januar!$Q$9,IF(A16="Mi",Januar!$Q$10,IF(A16="Do",Januar!$Q$11,IF(A16="Fr",Januar!$Q$12,Januar!$Q$13))))) -> 0
A17: So | B17: 10. | I17: =D17-C17-F17+E17-H17+G17+N17+O17 -> 0 | J17: =R17 -> 0 | M17: =IF(OR(K17="U",K17="K"),J17,"0:00") -> 0:00 | N17: =IF(M17<>"0:00",J17,"0:00") -> 0:00 | O17: =IF(K17="0,5 U","03:51","0:00") -> 0:00 | R17: =IF(A17="Mo",Januar!$Q$8,IF(A17="Di",Januar!$Q$9,IF(A17="Mi",Januar!$Q$10,IF(A17="Do",Januar!$Q$11,IF(A17="Fr",Januar!$Q$12,Januar!$Q$13))))) -> 0
A18: Mo | B18: 11. | C18: 0.35416667 | D18: 0.51041667 | I18: =D18-C18-F18+E18-H18+G18+N18+O18 -> 0.15625 | J18: =R18 -> 0.16666667 | M18: =IF(OR(K18="U",K18="K"),J18,"0:00") -> 0:00 | N18: =IF(M18<>"0:00",J18,"0:00") -> 0:00 | O18: =IF(K18="0,5 U","03:51","0:00") -> 0:00 | R18: =IF(A18="Mo",Januar!$Q$8,IF(A18="Di",Januar!$Q$9,IF(A18="Mi",Januar!$Q$10,IF(A18="Do",Januar!$Q$11,IF(A18="Fr",Januar!$Q$12,Januar!$Q$13))))) -> 0.16666667
A19: Di | B19: 12. | C19: 0.38541667 | D19: 0.66666667 | E19: 0.51041667 | F19: 0.53125 | I19: =D19-C19-F19+E19-H19+G19+N19+O19 -> 0.26041667 | J19: =R19 -> 0.16666667 | M19: =IF(OR(K19="U",K19="K"),J19,"0:00") -> 0:00 | N19: =IF(M19<>"0:00",J19,"0:00") -> 0:00 | O19: =IF(K19="0,5 U","03:51","0:00") -> 0:00 | R19: =IF(A19="Mo",Januar!$Q$8,IF(A19="Di",Januar!$Q$9,IF(A19="Mi",Januar!$Q$10,IF(A19="Do",Januar!$Q$11,IF(A19="Fr",Januar!$Q$12,Januar!$Q$13))))) -> 0.16666667
A20: Mi | B20: 13. | C20: 0.38541667 | D20: 0.51041667 | I20: =D20-C20-F20+E20-H20+G20+N20+O20 -> 0.125 | J20: =R20 -> 0.16666667 | M20: =IF(OR(K20="U",K20="K"),J20,"0:00") -> 0:00 | N20: =IF(M20<>"0:00",J20,"0:00") -> 0:00 | O20: =IF(K20="0,5 U","03:51","0:00") -> 0:00 | R20: =IF(A20="Mo",Januar!$Q$8,IF(A20="Di",Januar!$Q$9,IF(A20="Mi",Januar!$Q$10,IF(A20="Do",Januar!$Q$11,IF(A20="Fr",Januar!$Q$12,Januar!$Q$13))))) -> 0.16666667
A21: Do | B21: 14. | C21: 0.375 | D21: 0.5 | I21: =D21-C21-F21+E21-H21+G21+N21+O21 -> 0.125 | J21: 0 | M21: =IF(OR(K21="U",K21="K"),J21,"0:00") -> 0:00 | N21: =IF(M21<>"0:00",J21,"0:00") -> 0:00 | O21: =IF(K21="0,5 U","03:51","0:00") -> 0:00 | R21: =IF(A21="Mo",Januar!$Q$8,IF(A21="Di",Januar!$Q$9,IF(A21="Mi",Januar!$Q$10,IF(A21="Do",Januar!$Q$11,IF(A21="Fr",Januar!$Q$12,Januar!$Q$13))))) -> 0.16666667
A22: Fr | B22: 15. | I22: =D22-C22-F22+E22-H22+G22+N22+O22 -> 0 | J22: =R22 -> 0 | M22: =IF(OR(K22="U",K22="K"),J22,"0:00") -> 0:00 | N22: =IF(M22<>"0:00",J22,"0:00") -> 0:00 | O22: =IF(K22="0,5 U","03:51","0:00") -> 0:00 | R22: =IF(A22="Mo",Januar!$Q$8,IF(A22="Di",Januar!$Q$9,IF(A22="Mi",Januar!$Q$10,IF(A22="Do",Januar!$Q$11,IF(A22="Fr",Januar!$Q$12,Januar!$Q$13))))) -> 0
A23: Sa | B23: 16. | I23: =D23-C23-F23+E23-H23+G23+N23+O23 -> 0 | J23: =R23 -> 0 | M23: =IF(OR(K23="U",K23="K"),J23,"0:00") -> 0:00 | N23: =IF(M23<>"0:00",J23,"0:00") -> 0:00 | O23: =IF(K23="0,5 U","03:51","0:00") -> 0:00 | R23: =IF(A23="Mo",Januar!$Q$8,IF(A23="Di",Januar!$Q$9,IF(A23="Mi",Januar!$Q$10,IF(A23="Do",Januar!$Q$11,IF(A23="Fr",Januar!$Q$12,Januar!$Q$13))))) -> 0
A24: So | B24: 17. | I24: =D24-C24-F24+E24-H24+G24+N24+O24 -> 0 | J24: =R24 -> 0 | M24: =IF(OR(K24="U",K24="K"),J24,"0:00") -> 0:00 | N24: =IF(M24<>"0:00",J24,"0:00") -> 0:00 | O24: =IF(K24="0,5 U","03:51","0:00") -> 0:00 | R24: =IF(A24="Mo",Januar!$Q$8,IF(A24="Di",Januar!$Q$9,IF(A24="Mi",Januar!$Q$10,IF(A24="Do",Januar!$Q$11,IF(A24="Fr",Januar!$Q$12,Januar!$Q$13))))) -> 0
A25: Mo | B25: 18. | C25: 0.35416667 | D25: 0.51041667 | I25: =D25-C25-F25+E25-H25+G25+N25+O25 -> 0.15625 | J25: =R25 -> 0.16666667 | M25: =IF(OR(K25="U",K25="K"),J25,"0:00") -> 0:00 | N25: =IF(M25<>"0:00",J25,"0:00") -> 0:00 | O25: =IF(K25="0,5 U","03:51","0:00") -> 0:00 | R25: =IF(A25="Mo",Januar!$Q$8,IF(A25="Di",Januar!$Q$9,IF(A25="Mi",Januar!$Q$10,IF(A25="Do",Januar!$Q$11,IF(A25="Fr",Januar!$Q$12,Januar!$Q$13))))) -> 0.16666667
A26: Di | B26: 19. | C26: 0.38541667 | D26: 0.66666667 | E26: 0.51041667 | F26: 0.53125 | I26: =D26-C26-F26+E26-H26+G26+N26+O26 -> 0.26041667 | J26: =R26 -> 0.16666667 | M26: =IF(OR(K26="U",K26="K"),J26,"0:00") -> 0:00 | N26: =IF(M26<>"0:00",J26,"0:00") -> 0:00 | O26: =IF(K26="0,5 U","03:51","0:00") -> 0:00 | R26: =IF(A26="Mo",Januar!$Q$8,IF(A26="Di",Januar!$Q$9,IF(A26="Mi",Januar!$Q$10,IF(A26="Do",Januar!$Q$11,IF(A26="Fr",Januar!$Q$12,Januar!$Q$13))))) -> 0.16666667
A27: Mi | B27: 20. | C27: 0.38541667 | D27: 0.51041667 | I27: =D27-C27-F27+E27-H27+G27+N27+O27 -> 0.125 | J27: =R27 -> 0.16666667 | M27: =IF(OR(K27="U",K27="K"),J27,"0:00") -> 0:00 | N27: =IF(M27<>"0:00",J27,"0:00") -> 0:00 | O27: =IF(K27="0,5 U","03:51","0:00") -> 0:00 | R27: =IF(A27="Mo",Januar!$Q$8,IF(A27="Di",Januar!$Q$9,IF(A27="Mi",Januar!$Q$10,IF(A27="Do",Januar!$Q$11,IF(A27="Fr",Januar!$Q$12,Januar!$Q$13))))) -> 0.16666667
